INFO 2019-09-09 11:05:28,595 basehttp 124 "GET / HTTP/1.1" 200 1714
WARNING 2019-09-09 11:05:28,704 base 152 Not Found: /favicon.ico
WARNING 2019-09-09 11:05:28,709 basehttp 124 "GET /favicon.ico HTTP/1.1" 404 1967
WARNING 2019-09-10 14:10:56,402 base 152 Not Found: /
WARNING 2019-09-10 14:10:56,408 basehttp 124 "GET / HTTP/1.1" 404 2106
WARNING 2019-09-10 14:10:57,249 base 152 Not Found: /favicon.ico
WARNING 2019-09-10 14:10:57,266 basehttp 124 "GET /favicon.ico HTTP/1.1" 404 2157
WARNING 2019-09-10 14:12:16,081 base 152 Not Found: /
WARNING 2019-09-10 14:12:16,085 basehttp 124 "GET / HTTP/1.1" 404 2106
WARNING 2019-09-10 14:12:16,423 base 152 Not Found: /favicon.ico
WARNING 2019-09-10 14:12:16,423 basehttp 124 "GET /favicon.ico HTTP/1.1" 404 2157
WARNING 2019-09-10 14:13:04,990 base 152 Not Found: /
WARNING 2019-09-10 14:13:04,991 basehttp 124 "GET / HTTP/1.1" 404 2106
WARNING 2019-09-10 14:13:05,340 base 152 Not Found: /favicon.ico
WARNING 2019-09-10 14:13:05,343 basehttp 124 "GET /favicon.ico HTTP/1.1" 404 2157
WARNING 2019-09-10 14:20:02,602 base 152 Not Found: /sms_code/13789898989
WARNING 2019-09-10 14:20:02,606 basehttp 124 "GET /sms_code/13789898989 HTTP/1.1" 404 2184
INFO 2019-09-10 14:20:32,250 basehttp 124 "GET /sms_codes/13789898989 HTTP/1.1" 301 0
ERROR 2019-09-10 14:20:32,266 exception 135 Internal Server Error: /sms_codes/13789898989/
Traceback (most recent call last):
  File "/home/changle-lab/.virtualenvs/shoppingMall/lib/python3.6/site-packages/django/core/handlers/exception.py", line 41, in inner
    response = get_response(request)
  File "/home/changle-lab/.virtualenvs/shoppingMall/lib/python3.6/site-packages/django/core/handlers/base.py", line 187, in _get_response
    response = self.process_exception_by_middleware(e, request)
  File "/home/changle-lab/.virtualenvs/shoppingMall/lib/python3.6/site-packages/django/core/handlers/base.py", line 185, in _get_response
    response = wrapped_callback(request, *callback_args, **callback_kwargs)
  File "/home/changle-lab/.virtualenvs/shoppingMall/lib/python3.6/site-packages/django/views/decorators/csrf.py", line 58, in wrapped_view
    return view_func(*args, **kwargs)
  File "/home/changle-lab/.virtualenvs/shoppingMall/lib/python3.6/site-packages/django/views/generic/base.py", line 68, in view
    return self.dispatch(request, *args, **kwargs)
  File "/home/changle-lab/.virtualenvs/shoppingMall/lib/python3.6/site-packages/rest_framework/views.py", line 483, in dispatch
    response = self.handle_exception(exc)
  File "/home/changle-lab/.virtualenvs/shoppingMall/lib/python3.6/site-packages/rest_framework/views.py", line 443, in handle_exception
    self.raise_uncaught_exception(exc)
  File "/home/changle-lab/.virtualenvs/shoppingMall/lib/python3.6/site-packages/rest_framework/views.py", line 480, in dispatch
    response = handler(request, *args, **kwargs)
  File "/home/changle-lab/Desktop/shopping_mall/shoppingMall/meiduo_mall/meiduo_mall/apps/users/views.py", line 23, in get
    conn = get_redis_connection('sms_code')
  File "/home/changle-lab/.virtualenvs/shoppingMall/lib/python3.6/site-packages/django_redis/__init__.py", line 14, in get_redis_connection
    cache = caches[alias]
  File "/home/changle-lab/.virtualenvs/shoppingMall/lib/python3.6/site-packages/django/core/cache/__init__.py", line 77, in __getitem__
    "Could not find config for '%s' in settings.CACHES" % alias
django.core.cache.backends.base.InvalidCacheBackendError: Could not find config for 'sms_code' in settings.CACHES
ERROR 2019-09-10 14:20:32,329 basehttp 124 "GET /sms_codes/13789898989/ HTTP/1.1" 500 18396
INFO 2019-09-10 14:20:51,903 basehttp 124 "GET /sms_codes/13789898989 HTTP/1.1" 301 0
ERROR 2019-09-10 14:20:51,952 exception 135 Internal Server Error: /sms_codes/13789898989/
Traceback (most recent call last):
  File "/home/changle-lab/.virtualenvs/shoppingMall/lib/python3.6/site-packages/django/core/handlers/exception.py", line 41, in inner
    response = get_response(request)
  File "/home/changle-lab/.virtualenvs/shoppingMall/lib/python3.6/site-packages/django/core/handlers/base.py", line 187, in _get_response
    response = self.process_exception_by_middleware(e, request)
  File "/home/changle-lab/.virtualenvs/shoppingMall/lib/python3.6/site-packages/django/core/handlers/base.py", line 185, in _get_response
    response = wrapped_callback(request, *callback_args, **callback_kwargs)
  File "/home/changle-lab/.virtualenvs/shoppingMall/lib/python3.6/site-packages/django/views/decorators/csrf.py", line 58, in wrapped_view
    return view_func(*args, **kwargs)
  File "/home/changle-lab/.virtualenvs/shoppingMall/lib/python3.6/site-packages/django/views/generic/base.py", line 68, in view
    return self.dispatch(request, *args, **kwargs)
  File "/home/changle-lab/.virtualenvs/shoppingMall/lib/python3.6/site-packages/rest_framework/views.py", line 483, in dispatch
    response = self.handle_exception(exc)
  File "/home/changle-lab/.virtualenvs/shoppingMall/lib/python3.6/site-packages/rest_framework/views.py", line 443, in handle_exception
    self.raise_uncaught_exception(exc)
  File "/home/changle-lab/.virtualenvs/shoppingMall/lib/python3.6/site-packages/rest_framework/views.py", line 480, in dispatch
    response = handler(request, *args, **kwargs)
  File "/home/changle-lab/Desktop/shopping_mall/shoppingMall/meiduo_mall/meiduo_mall/apps/users/views.py", line 23, in get
    conn = get_redis_connection('sms_code')
  File "/home/changle-lab/.virtualenvs/shoppingMall/lib/python3.6/site-packages/django_redis/__init__.py", line 14, in get_redis_connection
    cache = caches[alias]
  File "/home/changle-lab/.virtualenvs/shoppingMall/lib/python3.6/site-packages/django/core/cache/__init__.py", line 77, in __getitem__
    "Could not find config for '%s' in settings.CACHES" % alias
django.core.cache.backends.base.InvalidCacheBackendError: Could not find config for 'sms_code' in settings.CACHES
ERROR 2019-09-10 14:20:52,003 basehttp 124 "GET /sms_codes/13789898989/ HTTP/1.1" 500 18396
INFO 2019-09-10 14:26:04,895 basehttp 124 "GET /sms_codes/13789898989 HTTP/1.1" 301 0
ERROR 2019-09-10 14:26:04,912 exception 135 Internal Server Error: /sms_codes/13789898989/
Traceback (most recent call last):
  File "/home/changle-lab/.virtualenvs/shoppingMall/lib/python3.6/site-packages/django/core/handlers/exception.py", line 41, in inner
    response = get_response(request)
  File "/home/changle-lab/.virtualenvs/shoppingMall/lib/python3.6/site-packages/django/core/handlers/base.py", line 187, in _get_response
    response = self.process_exception_by_middleware(e, request)
  File "/home/changle-lab/.virtualenvs/shoppingMall/lib/python3.6/site-packages/django/core/handlers/base.py", line 185, in _get_response
    response = wrapped_callback(request, *callback_args, **callback_kwargs)
  File "/home/changle-lab/.virtualenvs/shoppingMall/lib/python3.6/site-packages/django/views/decorators/csrf.py", line 58, in wrapped_view
    return view_func(*args, **kwargs)
  File "/home/changle-lab/.virtualenvs/shoppingMall/lib/python3.6/site-packages/django/views/generic/base.py", line 68, in view
    return self.dispatch(request, *args, **kwargs)
  File "/home/changle-lab/.virtualenvs/shoppingMall/lib/python3.6/site-packages/rest_framework/views.py", line 483, in dispatch
    response = self.handle_exception(exc)
  File "/home/changle-lab/.virtualenvs/shoppingMall/lib/python3.6/site-packages/rest_framework/views.py", line 443, in handle_exception
    self.raise_uncaught_exception(exc)
  File "/home/changle-lab/.virtualenvs/shoppingMall/lib/python3.6/site-packages/rest_framework/views.py", line 480, in dispatch
    response = handler(request, *args, **kwargs)
  File "/home/changle-lab/Desktop/shopping_mall/shoppingMall/meiduo_mall/meiduo_mall/apps/users/views.py", line 26, in get
    ccp = CCP()
  File "/home/changle-lab/Desktop/shopping_mall/shoppingMall/meiduo_mall/meiduo_mall/apps/libs/yuntongxun/sms.py", line 53, in __new__
    cls._instance.rest = REST(_serverIP, _serverPort, _softVersion)
NameError: name 'REST' is not defined
ERROR 2019-09-10 14:26:04,946 basehttp 124 "GET /sms_codes/13789898989/ HTTP/1.1" 500 18282
INFO 2019-09-10 14:30:24,356 basehttp 124 "GET /sms_codes/13789898989 HTTP/1.1" 301 0
INFO 2019-09-10 14:30:24,684 basehttp 124 "GET /sms_codes/13789898989/ HTTP/1.1" 200 4
INFO 2019-09-10 14:33:44,025 basehttp 124 "GET /sms_codes/13789898989 HTTP/1.1" 301 0
INFO 2019-09-10 14:33:44,313 basehttp 124 "GET /sms_codes/13789898989/ HTTP/1.1" 200 4
INFO 2019-09-10 15:50:20,740 basehttp 124 "GET /sms_codes/13789898989 HTTP/1.1" 301 0
INFO 2019-09-10 15:50:20,761 basehttp 124 "GET /sms_codes/13789898989/ HTTP/1.1" 200 4
INFO 2019-09-10 15:50:21,699 basehttp 124 "GET /sms_codes/13789898989 HTTP/1.1" 301 0
INFO 2019-09-10 15:50:21,706 basehttp 124 "GET /sms_codes/13789898989/ HTTP/1.1" 200 4
INFO 2019-09-10 15:50:23,265 basehttp 124 "GET /sms_codes/13789898989 HTTP/1.1" 301 0
INFO 2019-09-10 15:50:23,278 basehttp 124 "GET /sms_codes/13789898989/ HTTP/1.1" 200 4
INFO 2019-09-10 15:50:23,692 basehttp 124 "GET /sms_codes/13789898989 HTTP/1.1" 301 0
INFO 2019-09-10 15:50:23,700 basehttp 124 "GET /sms_codes/13789898989/ HTTP/1.1" 200 4
INFO 2019-09-10 15:50:24,256 basehttp 124 "GET /sms_codes/13789898989 HTTP/1.1" 301 0
INFO 2019-09-10 15:50:24,262 basehttp 124 "GET /sms_codes/13789898989/ HTTP/1.1" 200 4
INFO 2019-09-10 15:50:24,778 basehttp 124 "GET /sms_codes/13789898989 HTTP/1.1" 301 0
INFO 2019-09-10 15:50:24,786 basehttp 124 "GET /sms_codes/13789898989/ HTTP/1.1" 200 4
INFO 2019-09-10 15:50:25,206 basehttp 124 "GET /sms_codes/13789898989 HTTP/1.1" 301 0
INFO 2019-09-10 15:50:25,217 basehttp 124 "GET /sms_codes/13789898989/ HTTP/1.1" 200 4
INFO 2019-09-10 15:50:25,675 basehttp 124 "GET /sms_codes/13789898989 HTTP/1.1" 301 0
INFO 2019-09-10 15:50:25,693 basehttp 124 "GET /sms_codes/13789898989/ HTTP/1.1" 200 4
INFO 2019-09-10 15:50:26,077 basehttp 124 "GET /sms_codes/13789898989 HTTP/1.1" 301 0
INFO 2019-09-10 15:50:26,089 basehttp 124 "GET /sms_codes/13789898989/ HTTP/1.1" 200 4
INFO 2019-09-10 15:50:26,499 basehttp 124 "GET /sms_codes/13789898989 HTTP/1.1" 301 0
INFO 2019-09-10 15:50:26,504 basehttp 124 "GET /sms_codes/13789898989/ HTTP/1.1" 200 4
INFO 2019-09-10 15:50:27,569 basehttp 124 "GET /sms_codes/13789898989 HTTP/1.1" 301 0
INFO 2019-09-10 15:50:27,572 basehttp 124 "GET /sms_codes/13789898989/ HTTP/1.1" 200 4
INFO 2019-09-10 15:57:28,269 basehttp 124 "GET /sms_codes/13789898989 HTTP/1.1" 301 0
INFO 2019-09-10 15:57:28,559 basehttp 124 "GET /sms_codes/13789898989/ HTTP/1.1" 200 4
INFO 2019-09-10 15:57:32,652 basehttp 124 "GET /sms_codes/13789898989 HTTP/1.1" 301 0
WARNING 2019-09-10 15:57:32,671 basehttp 124 "GET /sms_codes/13789898989/ HTTP/1.1" 403 30
INFO 2019-09-10 17:35:16,220 basehttp 124 "GET /sms_codes/13789898989 HTTP/1.1" 301 0
INFO 2019-09-10 17:35:16,330 basehttp 124 "GET /sms_codes/13789898989/ HTTP/1.1" 200 4
WARNING 2019-09-10 22:07:57,526 base 152 Not Found: /mobiles/17310115251/count/
WARNING 2019-09-10 22:07:57,530 basehttp 124 "GET /mobiles/17310115251/count/ HTTP/1.1" 404 2208
WARNING 2019-09-10 22:07:57,643 base 152 Not Found: /mobiles/17310115251/count/
WARNING 2019-09-10 22:07:57,645 basehttp 124 "GET /mobiles/17310115251/count/ HTTP/1.1" 404 2208
INFO 2019-09-10 22:07:57,713 basehttp 124 "GET /sms_codes/17310115251/ HTTP/1.1" 200 4
WARNING 2019-09-10 22:57:57,009 base 152 Not Found: /mobiles/17310115251/count/
WARNING 2019-09-10 22:57:57,013 basehttp 124 "GET /mobiles/17310115251/count/ HTTP/1.1" 404 2208
WARNING 2019-09-10 22:57:57,172 base 152 Not Found: /mobiles/17310115251/count/
WARNING 2019-09-10 22:57:57,174 basehttp 124 "GET /mobiles/17310115251/count/ HTTP/1.1" 404 2208
INFO 2019-09-10 22:57:57,224 basehttp 124 "GET /sms_codes/17310115251/ HTTP/1.1" 200 4
WARNING 2019-09-10 23:17:47,045 base 152 Not Found: /
WARNING 2019-09-10 23:17:47,046 basehttp 124 "GET / HTTP/1.1" 404 2106
WARNING 2019-09-10 23:17:47,178 base 152 Not Found: /favicon.ico
WARNING 2019-09-10 23:17:47,180 basehttp 124 "GET /favicon.ico HTTP/1.1" 404 2157
WARNING 2019-09-10 23:18:19,345 base 152 Not Found: /
WARNING 2019-09-10 23:18:19,350 basehttp 124 "GET / HTTP/1.1" 404 2112
WARNING 2019-09-10 23:18:19,448 base 152 Not Found: /favicon.ico
WARNING 2019-09-10 23:18:19,450 basehttp 124 "GET /favicon.ico HTTP/1.1" 404 2163
WARNING 2019-09-10 23:18:31,139 base 152 Not Found: /
WARNING 2019-09-10 23:18:31,149 basehttp 124 "GET / HTTP/1.1" 404 2112
ERROR 2019-09-10 23:19:10,819 exception 80 Invalid HTTP_HOST header: 'www.meiduo.site:8000'. You may need to add 'www.meiduo.site' to ALLOWED_HOSTS.
WARNING 2019-09-10 23:19:10,935 basehttp 124 "GET / HTTP/1.1" 400 71720
ERROR 2019-09-10 23:19:11,157 exception 80 Invalid HTTP_HOST header: 'www.meiduo.site:8000'. You may need to add 'www.meiduo.site' to ALLOWED_HOSTS.
WARNING 2019-09-10 23:19:11,211 basehttp 124 "GET /favicon.ico HTTP/1.1" 400 71771
WARNING 2019-09-10 23:20:05,062 base 152 Not Found: /usernames/ffdsffasfasd/count/
WARNING 2019-09-10 23:20:05,063 basehttp 124 "GET /usernames/ffdsffasfasd/count/ HTTP/1.1" 404 2217
ERROR 2019-09-10 23:22:12,808 exception 80 Invalid HTTP_HOST header: 'api.meiduo.site:8000'. You may need to add 'api.meiduo.site' to ALLOWED_HOSTS.
WARNING 2019-09-10 23:22:12,867 basehttp 124 "GET /usernames/ffffff/count/ HTTP/1.1" 400 72317
WARNING 2019-09-10 23:24:02,394 base 152 Not Found: /usernames/grgggg/count/
WARNING 2019-09-10 23:24:02,405 basehttp 124 "GET /usernames/grgggg/count/ HTTP/1.1" 404 2199
WARNING 2019-09-10 23:43:33,670 base 152 Not Found: /usernames/python/count/
WARNING 2019-09-10 23:43:33,672 basehttp 124 "GET /usernames/python/count/ HTTP/1.1" 404 2383
WARNING 2019-09-10 23:44:27,083 base 152 Not Found: /usernames/python/count/
WARNING 2019-09-10 23:44:27,089 basehttp 124 "GET /usernames/python/count/ HTTP/1.1" 404 2383
WARNING 2019-09-10 23:45:26,149 base 152 Not Found: /usernames/fffffff/count/
WARNING 2019-09-10 23:45:26,151 basehttp 124 "GET /usernames/fffffff/count/ HTTP/1.1" 404 2385
WARNING 2019-09-10 23:46:04,836 base 152 Not Found: /usernames/fefefefefe/count/
WARNING 2019-09-10 23:46:04,837 basehttp 124 "GET /usernames/fefefefefe/count/ HTTP/1.1" 404 2395
INFO 2019-09-10 23:48:48,175 basehttp 124 "GET /usernames/fffffffff/count/ HTTP/1.1" 200 11
INFO 2019-09-10 23:49:30,925 basehttp 124 "GET /usernames/333333/count/ HTTP/1.1" 200 11
INFO 2019-09-11 00:01:42,573 basehttp 124 "GET /usernames/333333/count/ HTTP/1.1" 200 11
INFO 2019-09-11 00:03:03,645 basehttp 124 "GET /usernames/333333/count/ HTTP/1.1" 200 11
INFO 2019-09-11 00:03:22,665 basehttp 124 "GET /usernames/17310115251/count/ HTTP/1.1" 200 11
INFO 2019-09-11 00:03:29,541 basehttp 124 "GET /usernames/17310115251/count/ HTTP/1.1" 200 11
WARNING 2019-09-11 00:04:03,029 base 152 Not Found: /mobiles/17388998899/count/
WARNING 2019-09-11 00:04:03,032 basehttp 124 "GET /mobiles/17388998899/count/ HTTP/1.1" 404 2398
WARNING 2019-09-11 00:05:01,263 base 152 Not Found: /mobiles/17388998899/count/
WARNING 2019-09-11 00:05:01,264 basehttp 124 "GET /mobiles/17388998899/count/ HTTP/1.1" 404 2398
INFO 2019-09-11 00:08:44,144 basehttp 124 "GET /mobiles/18899999999/count/ HTTP/1.1" 200 11
INFO 2019-09-11 00:09:15,305 basehttp 124 "GET /mobiles/17398765678/count/ HTTP/1.1" 200 11
INFO 2019-09-11 00:50:06,218 basehttp 124 "GET /usernames/python/count/ HTTP/1.1" 200 11
INFO 2019-09-11 00:50:18,917 basehttp 124 "GET /mobiles/17389898989/count/ HTTP/1.1" 200 11
INFO 2019-09-11 00:50:19,148 basehttp 124 "GET /mobiles/17389898989/count/ HTTP/1.1" 200 11
INFO 2019-09-11 00:50:19,222 basehttp 124 "GET /sms_codes/17389898989/ HTTP/1.1" 200 4
INFO 2019-09-11 00:50:36,270 basehttp 124 "OPTIONS /users/ HTTP/1.1" 200 0
WARNING 2019-09-11 00:50:36,291 base 152 Not Found: /users/
WARNING 2019-09-11 00:50:36,294 basehttp 124 "POST /users/ HTTP/1.1" 404 2533
INFO 2019-09-11 00:50:36,301 basehttp 124 "GET /usernames/python/count/ HTTP/1.1" 200 11
INFO 2019-09-11 00:50:36,305 basehttp 124 "GET /mobiles/17389898989/count/ HTTP/1.1" 200 11
WARNING 2019-09-11 00:50:43,414 base 152 Not Found: /users/
INFO 2019-09-11 00:50:43,421 basehttp 124 "GET /usernames/python/count/ HTTP/1.1" 200 11
INFO 2019-09-11 00:50:43,426 basehttp 124 "GET /mobiles/17389898989/count/ HTTP/1.1" 200 11
WARNING 2019-09-11 00:50:43,429 basehttp 124 "POST /users/ HTTP/1.1" 404 2533
INFO 2019-09-11 00:54:20,884 basehttp 124 "GET /usernames/python/count/ HTTP/1.1" 200 11
INFO 2019-09-11 00:54:33,905 basehttp 124 "GET /mobiles/17387878787/count/ HTTP/1.1" 200 11
INFO 2019-09-11 00:54:34,110 basehttp 124 "GET /mobiles/17387878787/count/ HTTP/1.1" 200 11
INFO 2019-09-11 00:54:34,138 basehttp 124 "GET /sms_codes/17387878787/ HTTP/1.1" 200 4
INFO 2019-09-11 00:54:50,483 basehttp 124 "GET /usernames/python/count/ HTTP/1.1" 200 11
INFO 2019-09-11 00:54:50,494 basehttp 124 "GET /mobiles/17387878787/count/ HTTP/1.1" 200 11
ERROR 2019-09-11 00:54:50,516 exception 135 Internal Server Error: /users/
Traceback (most recent call last):
  File "/home/changle-lab/.virtualenvs/shoppingMall/lib/python3.6/site-packages/rest_framework/serializers.py", line 940, in create
    instance = ModelClass.objects.create(**validated_data)
  File "/home/changle-lab/.virtualenvs/shoppingMall/lib/python3.6/site-packages/django/db/models/manager.py", line 85, in manager_method
    return getattr(self.get_queryset(), name)(*args, **kwargs)
  File "/home/changle-lab/.virtualenvs/shoppingMall/lib/python3.6/site-packages/django/db/models/query.py", line 392, in create
    obj = self.model(**kwargs)
  File "/home/changle-lab/.virtualenvs/shoppingMall/lib/python3.6/site-packages/django/contrib/auth/base_user.py", line 68, in __init__
    super(AbstractBaseUser, self).__init__(*args, **kwargs)
  File "/home/changle-lab/.virtualenvs/shoppingMall/lib/python3.6/site-packages/django/db/models/base.py", line 573, in __init__
    raise TypeError("'%s' is an invalid keyword argument for this function" % list(kwargs)[0])
TypeError: 'password2' is an invalid keyword argument for this function

During handling of the above exception, another exception occurred:

Traceback (most recent call last):
  File "/home/changle-lab/.virtualenvs/shoppingMall/lib/python3.6/site-packages/django/core/handlers/exception.py", line 41, in inner
    response = get_response(request)
  File "/home/changle-lab/.virtualenvs/shoppingMall/lib/python3.6/site-packages/django/core/handlers/base.py", line 187, in _get_response
    response = self.process_exception_by_middleware(e, request)
  File "/home/changle-lab/.virtualenvs/shoppingMall/lib/python3.6/site-packages/django/core/handlers/base.py", line 185, in _get_response
    response = wrapped_callback(request, *callback_args, **callback_kwargs)
  File "/home/changle-lab/.virtualenvs/shoppingMall/lib/python3.6/site-packages/django/views/decorators/csrf.py", line 58, in wrapped_view
    return view_func(*args, **kwargs)
  File "/home/changle-lab/.virtualenvs/shoppingMall/lib/python3.6/site-packages/django/views/generic/base.py", line 68, in view
    return self.dispatch(request, *args, **kwargs)
  File "/home/changle-lab/.virtualenvs/shoppingMall/lib/python3.6/site-packages/rest_framework/views.py", line 483, in dispatch
    response = self.handle_exception(exc)
  File "/home/changle-lab/.virtualenvs/shoppingMall/lib/python3.6/site-packages/rest_framework/views.py", line 443, in handle_exception
    self.raise_uncaught_exception(exc)
  File "/home/changle-lab/.virtualenvs/shoppingMall/lib/python3.6/site-packages/rest_framework/views.py", line 480, in dispatch
    response = handler(request, *args, **kwargs)
  File "/home/changle-lab/.virtualenvs/shoppingMall/lib/python3.6/site-packages/rest_framework/generics.py", line 192, in post
    return self.create(request, *args, **kwargs)
  File "/home/changle-lab/.virtualenvs/shoppingMall/lib/python3.6/site-packages/rest_framework/mixins.py", line 21, in create
    self.perform_create(serializer)
  File "/home/changle-lab/.virtualenvs/shoppingMall/lib/python3.6/site-packages/rest_framework/mixins.py", line 26, in perform_create
    serializer.save()
  File "/home/changle-lab/.virtualenvs/shoppingMall/lib/python3.6/site-packages/rest_framework/serializers.py", line 214, in save
    self.instance = self.create(validated_data)
  File "/home/changle-lab/.virtualenvs/shoppingMall/lib/python3.6/site-packages/rest_framework/serializers.py", line 957, in create
    raise TypeError(msg)
TypeError: Got a `TypeError` when calling `User.objects.create()`. This may be because you have a writable field on the serializer class that is not a valid argument to `User.objects.create()`. You may need to make the field read-only, or override the UserSerializers.create() method to handle this correctly.
Original exception was:
 Traceback (most recent call last):
  File "/home/changle-lab/.virtualenvs/shoppingMall/lib/python3.6/site-packages/rest_framework/serializers.py", line 940, in create
    instance = ModelClass.objects.create(**validated_data)
  File "/home/changle-lab/.virtualenvs/shoppingMall/lib/python3.6/site-packages/django/db/models/manager.py", line 85, in manager_method
    return getattr(self.get_queryset(), name)(*args, **kwargs)
  File "/home/changle-lab/.virtualenvs/shoppingMall/lib/python3.6/site-packages/django/db/models/query.py", line 392, in create
    obj = self.model(**kwargs)
  File "/home/changle-lab/.virtualenvs/shoppingMall/lib/python3.6/site-packages/django/contrib/auth/base_user.py", line 68, in __init__
    super(AbstractBaseUser, self).__init__(*args, **kwargs)
  File "/home/changle-lab/.virtualenvs/shoppingMall/lib/python3.6/site-packages/django/db/models/base.py", line 573, in __init__
    raise TypeError("'%s' is an invalid keyword argument for this function" % list(kwargs)[0])
TypeError: 'password2' is an invalid keyword argument for this function

ERROR 2019-09-11 00:54:50,568 basehttp 124 "POST /users/ HTTP/1.1" 500 22990
INFO 2019-09-11 00:57:17,208 basehttp 124 "GET /mobiles/17387878787/count/ HTTP/1.1" 200 11
INFO 2019-09-11 00:58:00,473 basehttp 124 "GET /usernames/python/count/ HTTP/1.1" 200 11
INFO 2019-09-11 00:58:26,956 basehttp 124 "GET /mobiles/17387878787/count/ HTTP/1.1" 200 11
INFO 2019-09-11 00:58:33,233 basehttp 124 "GET /mobiles/17387878787/count/ HTTP/1.1" 200 11
INFO 2019-09-11 00:58:33,269 basehttp 124 "GET /sms_codes/17387878787/ HTTP/1.1" 200 4
INFO 2019-09-11 00:58:59,310 basehttp 124 "GET /usernames/python/count/ HTTP/1.1" 200 11
INFO 2019-09-11 00:58:59,313 basehttp 124 "GET /mobiles/17387878787/count/ HTTP/1.1" 200 11
ERROR 2019-09-11 00:58:59,326 exception 135 Internal Server Error: /users/
Traceback (most recent call last):
  File "/home/changle-lab/.virtualenvs/shoppingMall/lib/python3.6/site-packages/rest_framework/serializers.py", line 940, in create
    instance = ModelClass.objects.create(**validated_data)
  File "/home/changle-lab/.virtualenvs/shoppingMall/lib/python3.6/site-packages/django/db/models/manager.py", line 85, in manager_method
    return getattr(self.get_queryset(), name)(*args, **kwargs)
  File "/home/changle-lab/.virtualenvs/shoppingMall/lib/python3.6/site-packages/django/db/models/query.py", line 392, in create
    obj = self.model(**kwargs)
  File "/home/changle-lab/.virtualenvs/shoppingMall/lib/python3.6/site-packages/django/contrib/auth/base_user.py", line 68, in __init__
    super(AbstractBaseUser, self).__init__(*args, **kwargs)
  File "/home/changle-lab/.virtualenvs/shoppingMall/lib/python3.6/site-packages/django/db/models/base.py", line 573, in __init__
    raise TypeError("'%s' is an invalid keyword argument for this function" % list(kwargs)[0])
TypeError: 'password2' is an invalid keyword argument for this function

During handling of the above exception, another exception occurred:

Traceback (most recent call last):
  File "/home/changle-lab/.virtualenvs/shoppingMall/lib/python3.6/site-packages/django/core/handlers/exception.py", line 41, in inner
    response = get_response(request)
  File "/home/changle-lab/.virtualenvs/shoppingMall/lib/python3.6/site-packages/django/core/handlers/base.py", line 187, in _get_response
    response = self.process_exception_by_middleware(e, request)
  File "/home/changle-lab/.virtualenvs/shoppingMall/lib/python3.6/site-packages/django/core/handlers/base.py", line 185, in _get_response
    response = wrapped_callback(request, *callback_args, **callback_kwargs)
  File "/home/changle-lab/.virtualenvs/shoppingMall/lib/python3.6/site-packages/django/views/decorators/csrf.py", line 58, in wrapped_view
    return view_func(*args, **kwargs)
  File "/home/changle-lab/.virtualenvs/shoppingMall/lib/python3.6/site-packages/django/views/generic/base.py", line 68, in view
    return self.dispatch(request, *args, **kwargs)
  File "/home/changle-lab/.virtualenvs/shoppingMall/lib/python3.6/site-packages/rest_framework/views.py", line 483, in dispatch
    response = self.handle_exception(exc)
  File "/home/changle-lab/.virtualenvs/shoppingMall/lib/python3.6/site-packages/rest_framework/views.py", line 443, in handle_exception
    self.raise_uncaught_exception(exc)
  File "/home/changle-lab/.virtualenvs/shoppingMall/lib/python3.6/site-packages/rest_framework/views.py", line 480, in dispatch
    response = handler(request, *args, **kwargs)
  File "/home/changle-lab/.virtualenvs/shoppingMall/lib/python3.6/site-packages/rest_framework/generics.py", line 192, in post
    return self.create(request, *args, **kwargs)
  File "/home/changle-lab/.virtualenvs/shoppingMall/lib/python3.6/site-packages/rest_framework/mixins.py", line 21, in create
    self.perform_create(serializer)
  File "/home/changle-lab/.virtualenvs/shoppingMall/lib/python3.6/site-packages/rest_framework/mixins.py", line 26, in perform_create
    serializer.save()
  File "/home/changle-lab/.virtualenvs/shoppingMall/lib/python3.6/site-packages/rest_framework/serializers.py", line 214, in save
    self.instance = self.create(validated_data)
  File "/home/changle-lab/.virtualenvs/shoppingMall/lib/python3.6/site-packages/rest_framework/serializers.py", line 957, in create
    raise TypeError(msg)
TypeError: Got a `TypeError` when calling `User.objects.create()`. This may be because you have a writable field on the serializer class that is not a valid argument to `User.objects.create()`. You may need to make the field read-only, or override the UserSerializers.create() method to handle this correctly.
Original exception was:
 Traceback (most recent call last):
  File "/home/changle-lab/.virtualenvs/shoppingMall/lib/python3.6/site-packages/rest_framework/serializers.py", line 940, in create
    instance = ModelClass.objects.create(**validated_data)
  File "/home/changle-lab/.virtualenvs/shoppingMall/lib/python3.6/site-packages/django/db/models/manager.py", line 85, in manager_method
    return getattr(self.get_queryset(), name)(*args, **kwargs)
  File "/home/changle-lab/.virtualenvs/shoppingMall/lib/python3.6/site-packages/django/db/models/query.py", line 392, in create
    obj = self.model(**kwargs)
  File "/home/changle-lab/.virtualenvs/shoppingMall/lib/python3.6/site-packages/django/contrib/auth/base_user.py", line 68, in __init__
    super(AbstractBaseUser, self).__init__(*args, **kwargs)
  File "/home/changle-lab/.virtualenvs/shoppingMall/lib/python3.6/site-packages/django/db/models/base.py", line 573, in __init__
    raise TypeError("'%s' is an invalid keyword argument for this function" % list(kwargs)[0])
TypeError: 'password2' is an invalid keyword argument for this function

ERROR 2019-09-11 00:58:59,358 basehttp 124 "POST /users/ HTTP/1.1" 500 22990
INFO 2019-09-11 01:10:09,153 basehttp 124 "GET /usernames/python/count/ HTTP/1.1" 200 11
INFO 2019-09-11 01:10:30,869 basehttp 124 "GET /mobiles/17354545454/count/ HTTP/1.1" 200 11
INFO 2019-09-11 01:10:31,090 basehttp 124 "GET /mobiles/17354545454/count/ HTTP/1.1" 200 11
INFO 2019-09-11 01:10:31,114 basehttp 124 "GET /sms_codes/17354545454/ HTTP/1.1" 200 4
INFO 2019-09-11 01:10:46,039 basehttp 124 "GET /mobiles/17354545454/count/ HTTP/1.1" 200 11
ERROR 2019-09-11 01:10:46,048 exception 135 Internal Server Error: /users/
Traceback (most recent call last):
  File "/home/changle-lab/.virtualenvs/shoppingMall/lib/python3.6/site-packages/rest_framework/serializers.py", line 940, in create
    instance = ModelClass.objects.create(**validated_data)
  File "/home/changle-lab/.virtualenvs/shoppingMall/lib/python3.6/site-packages/django/db/models/manager.py", line 85, in manager_method
    return getattr(self.get_queryset(), name)(*args, **kwargs)
  File "/home/changle-lab/.virtualenvs/shoppingMall/lib/python3.6/site-packages/django/db/models/query.py", line 392, in create
    obj = self.model(**kwargs)
  File "/home/changle-lab/.virtualenvs/shoppingMall/lib/python3.6/site-packages/django/contrib/auth/base_user.py", line 68, in __init__
    super(AbstractBaseUser, self).__init__(*args, **kwargs)
  File "/home/changle-lab/.virtualenvs/shoppingMall/lib/python3.6/site-packages/django/db/models/base.py", line 573, in __init__
    raise TypeError("'%s' is an invalid keyword argument for this function" % list(kwargs)[0])
TypeError: 'password2' is an invalid keyword argument for this function

During handling of the above exception, another exception occurred:

Traceback (most recent call last):
  File "/home/changle-lab/.virtualenvs/shoppingMall/lib/python3.6/site-packages/django/core/handlers/exception.py", line 41, in inner
    response = get_response(request)
  File "/home/changle-lab/.virtualenvs/shoppingMall/lib/python3.6/site-packages/django/core/handlers/base.py", line 187, in _get_response
    response = self.process_exception_by_middleware(e, request)
  File "/home/changle-lab/.virtualenvs/shoppingMall/lib/python3.6/site-packages/django/core/handlers/base.py", line 185, in _get_response
    response = wrapped_callback(request, *callback_args, **callback_kwargs)
  File "/home/changle-lab/.virtualenvs/shoppingMall/lib/python3.6/site-packages/django/views/decorators/csrf.py", line 58, in wrapped_view
    return view_func(*args, **kwargs)
  File "/home/changle-lab/.virtualenvs/shoppingMall/lib/python3.6/site-packages/django/views/generic/base.py", line 68, in view
    return self.dispatch(request, *args, **kwargs)
  File "/home/changle-lab/.virtualenvs/shoppingMall/lib/python3.6/site-packages/rest_framework/views.py", line 483, in dispatch
    response = self.handle_exception(exc)
  File "/home/changle-lab/.virtualenvs/shoppingMall/lib/python3.6/site-packages/rest_framework/views.py", line 443, in handle_exception
    self.raise_uncaught_exception(exc)
  File "/home/changle-lab/.virtualenvs/shoppingMall/lib/python3.6/site-packages/rest_framework/views.py", line 480, in dispatch
    response = handler(request, *args, **kwargs)
  File "/home/changle-lab/.virtualenvs/shoppingMall/lib/python3.6/site-packages/rest_framework/generics.py", line 192, in post
    return self.create(request, *args, **kwargs)
  File "/home/changle-lab/.virtualenvs/shoppingMall/lib/python3.6/site-packages/rest_framework/mixins.py", line 21, in create
    self.perform_create(serializer)
  File "/home/changle-lab/.virtualenvs/shoppingMall/lib/python3.6/site-packages/rest_framework/mixins.py", line 26, in perform_create
    serializer.save()
  File "/home/changle-lab/.virtualenvs/shoppingMall/lib/python3.6/site-packages/rest_framework/serializers.py", line 214, in save
    self.instance = self.create(validated_data)
  File "/home/changle-lab/.virtualenvs/shoppingMall/lib/python3.6/site-packages/rest_framework/serializers.py", line 957, in create
    raise TypeError(msg)
TypeError: Got a `TypeError` when calling `User.objects.create()`. This may be because you have a writable field on the serializer class that is not a valid argument to `User.objects.create()`. You may need to make the field read-only, or override the UserSerializers.create() method to handle this correctly.
Original exception was:
 Traceback (most recent call last):
  File "/home/changle-lab/.virtualenvs/shoppingMall/lib/python3.6/site-packages/rest_framework/serializers.py", line 940, in create
    instance = ModelClass.objects.create(**validated_data)
  File "/home/changle-lab/.virtualenvs/shoppingMall/lib/python3.6/site-packages/django/db/models/manager.py", line 85, in manager_method
    return getattr(self.get_queryset(), name)(*args, **kwargs)
  File "/home/changle-lab/.virtualenvs/shoppingMall/lib/python3.6/site-packages/django/db/models/query.py", line 392, in create
    obj = self.model(**kwargs)
  File "/home/changle-lab/.virtualenvs/shoppingMall/lib/python3.6/site-packages/django/contrib/auth/base_user.py", line 68, in __init__
    super(AbstractBaseUser, self).__init__(*args, **kwargs)
  File "/home/changle-lab/.virtualenvs/shoppingMall/lib/python3.6/site-packages/django/db/models/base.py", line 573, in __init__
    raise TypeError("'%s' is an invalid keyword argument for this function" % list(kwargs)[0])
TypeError: 'password2' is an invalid keyword argument for this function

INFO 2019-09-11 01:10:46,053 basehttp 124 "GET /usernames/python/count/ HTTP/1.1" 200 11
ERROR 2019-09-11 01:10:46,088 basehttp 124 "POST /users/ HTTP/1.1" 500 22990
INFO 2019-09-11 01:18:56,430 basehttp 124 "GET /usernames/python/count/ HTTP/1.1" 200 11
INFO 2019-09-11 01:19:24,668 basehttp 124 "GET /mobiles/17389898977/count/ HTTP/1.1" 200 11
INFO 2019-09-11 01:19:24,915 basehttp 124 "GET /mobiles/17389898977/count/ HTTP/1.1" 200 11
INFO 2019-09-11 01:19:24,955 basehttp 124 "GET /sms_codes/17389898977/ HTTP/1.1" 200 4
INFO 2019-09-11 01:19:45,843 basehttp 124 "GET /usernames/python/count/ HTTP/1.1" 200 11
INFO 2019-09-11 01:19:45,847 basehttp 124 "GET /mobiles/17389898977/count/ HTTP/1.1" 200 11
ERROR 2019-09-11 01:19:45,857 exception 135 Internal Server Error: /users/
Traceback (most recent call last):
  File "/home/changle-lab/.virtualenvs/shoppingMall/lib/python3.6/site-packages/django/core/handlers/exception.py", line 41, in inner
    response = get_response(request)
  File "/home/changle-lab/.virtualenvs/shoppingMall/lib/python3.6/site-packages/django/core/handlers/base.py", line 187, in _get_response
    response = self.process_exception_by_middleware(e, request)
  File "/home/changle-lab/.virtualenvs/shoppingMall/lib/python3.6/site-packages/django/core/handlers/base.py", line 185, in _get_response
    response = wrapped_callback(request, *callback_args, **callback_kwargs)
  File "/home/changle-lab/.virtualenvs/shoppingMall/lib/python3.6/site-packages/django/views/decorators/csrf.py", line 58, in wrapped_view
    return view_func(*args, **kwargs)
  File "/home/changle-lab/.virtualenvs/shoppingMall/lib/python3.6/site-packages/django/views/generic/base.py", line 68, in view
    return self.dispatch(request, *args, **kwargs)
  File "/home/changle-lab/.virtualenvs/shoppingMall/lib/python3.6/site-packages/rest_framework/views.py", line 483, in dispatch
    response = self.handle_exception(exc)
  File "/home/changle-lab/.virtualenvs/shoppingMall/lib/python3.6/site-packages/rest_framework/views.py", line 443, in handle_exception
    self.raise_uncaught_exception(exc)
  File "/home/changle-lab/.virtualenvs/shoppingMall/lib/python3.6/site-packages/rest_framework/views.py", line 480, in dispatch
    response = handler(request, *args, **kwargs)
  File "/home/changle-lab/.virtualenvs/shoppingMall/lib/python3.6/site-packages/rest_framework/generics.py", line 192, in post
    return self.create(request, *args, **kwargs)
  File "/home/changle-lab/.virtualenvs/shoppingMall/lib/python3.6/site-packages/rest_framework/mixins.py", line 20, in create
    serializer.is_valid(raise_exception=True)
  File "/home/changle-lab/.virtualenvs/shoppingMall/lib/python3.6/site-packages/rest_framework/serializers.py", line 236, in is_valid
    self._validated_data = self.run_validation(self.initial_data)
  File "/home/changle-lab/.virtualenvs/shoppingMall/lib/python3.6/site-packages/rest_framework/serializers.py", line 437, in run_validation
    value = self.validate(value)
  File "/home/changle-lab/Desktop/shopping_mall/shoppingMall/meiduo_mall/meiduo_mall/apps/users/serializers.py", line 124, in validate
    redis_conn = get_redis_connection('verify_codes')
NameError: name 'get_redis_connection' is not defined
ERROR 2019-09-11 01:19:45,884 basehttp 124 "POST /users/ HTTP/1.1" 500 19219
INFO 2019-09-11 01:20:31,595 basehttp 124 "GET /usernames/python/count/ HTTP/1.1" 200 11
INFO 2019-09-11 01:20:55,460 basehttp 124 "GET /mobiles/17365656565/count/ HTTP/1.1" 200 11
INFO 2019-09-11 01:20:55,675 basehttp 124 "GET /mobiles/17365656565/count/ HTTP/1.1" 200 11
INFO 2019-09-11 01:20:55,710 basehttp 124 "GET /sms_codes/17365656565/ HTTP/1.1" 200 4
INFO 2019-09-11 01:21:11,375 basehttp 124 "GET /usernames/python/count/ HTTP/1.1" 200 11
INFO 2019-09-11 01:21:11,382 basehttp 124 "GET /mobiles/17365656565/count/ HTTP/1.1" 200 11
ERROR 2019-09-11 01:21:11,384 exception 135 Internal Server Error: /users/
Traceback (most recent call last):
  File "/home/changle-lab/.virtualenvs/shoppingMall/lib/python3.6/site-packages/django/core/handlers/exception.py", line 41, in inner
    response = get_response(request)
  File "/home/changle-lab/.virtualenvs/shoppingMall/lib/python3.6/site-packages/django/core/handlers/base.py", line 187, in _get_response
    response = self.process_exception_by_middleware(e, request)
  File "/home/changle-lab/.virtualenvs/shoppingMall/lib/python3.6/site-packages/django/core/handlers/base.py", line 185, in _get_response
    response = wrapped_callback(request, *callback_args, **callback_kwargs)
  File "/home/changle-lab/.virtualenvs/shoppingMall/lib/python3.6/site-packages/django/views/decorators/csrf.py", line 58, in wrapped_view
    return view_func(*args, **kwargs)
  File "/home/changle-lab/.virtualenvs/shoppingMall/lib/python3.6/site-packages/django/views/generic/base.py", line 68, in view
    return self.dispatch(request, *args, **kwargs)
  File "/home/changle-lab/.virtualenvs/shoppingMall/lib/python3.6/site-packages/rest_framework/views.py", line 483, in dispatch
    response = self.handle_exception(exc)
  File "/home/changle-lab/.virtualenvs/shoppingMall/lib/python3.6/site-packages/rest_framework/views.py", line 443, in handle_exception
    self.raise_uncaught_exception(exc)
  File "/home/changle-lab/.virtualenvs/shoppingMall/lib/python3.6/site-packages/rest_framework/views.py", line 480, in dispatch
    response = handler(request, *args, **kwargs)
  File "/home/changle-lab/.virtualenvs/shoppingMall/lib/python3.6/site-packages/rest_framework/generics.py", line 192, in post
    return self.create(request, *args, **kwargs)
  File "/home/changle-lab/.virtualenvs/shoppingMall/lib/python3.6/site-packages/rest_framework/mixins.py", line 20, in create
    serializer.is_valid(raise_exception=True)
  File "/home/changle-lab/.virtualenvs/shoppingMall/lib/python3.6/site-packages/rest_framework/serializers.py", line 236, in is_valid
    self._validated_data = self.run_validation(self.initial_data)
  File "/home/changle-lab/.virtualenvs/shoppingMall/lib/python3.6/site-packages/rest_framework/serializers.py", line 437, in run_validation
    value = self.validate(value)
  File "/home/changle-lab/Desktop/shopping_mall/shoppingMall/meiduo_mall/meiduo_mall/apps/users/serializers.py", line 125, in validate
    redis_conn = get_redis_connection('verify_codes')
  File "/home/changle-lab/.virtualenvs/shoppingMall/lib/python3.6/site-packages/django_redis/__init__.py", line 14, in get_redis_connection
    cache = caches[alias]
  File "/home/changle-lab/.virtualenvs/shoppingMall/lib/python3.6/site-packages/django/core/cache/__init__.py", line 77, in __getitem__
    "Could not find config for '%s' in settings.CACHES" % alias
django.core.cache.backends.base.InvalidCacheBackendError: Could not find config for 'verify_codes' in settings.CACHES
ERROR 2019-09-11 01:21:11,412 basehttp 124 "POST /users/ HTTP/1.1" 500 19651
INFO 2019-09-11 01:23:27,230 basehttp 124 "GET /usernames/python/count/ HTTP/1.1" 200 11
INFO 2019-09-11 01:23:45,597 basehttp 124 "GET /mobiles/17357575757/count/ HTTP/1.1" 200 11
INFO 2019-09-11 01:23:45,784 basehttp 124 "GET /mobiles/17357575757/count/ HTTP/1.1" 200 11
INFO 2019-09-11 01:23:45,817 basehttp 124 "GET /sms_codes/17357575757/ HTTP/1.1" 200 4
INFO 2019-09-11 01:23:56,119 basehttp 124 "GET /mobiles/17357575757/count/ HTTP/1.1" 200 11
INFO 2019-09-11 01:23:56,129 basehttp 124 "GET /usernames/python/count/ HTTP/1.1" 200 11
INFO 2019-09-11 01:23:56,195 basehttp 124 "POST /users/ HTTP/1.1" 201 51
WARNING 2019-09-11 01:23:56,372 base 152 Not Found: /skus/search/
WARNING 2019-09-11 01:23:56,381 basehttp 124 "GET /skus/search/?page=1&page_size=6 HTTP/1.1" 404 2729
INFO 2019-09-11 01:24:49,579 basehttp 124 "OPTIONS /authorizations/ HTTP/1.1" 200 0
WARNING 2019-09-11 01:24:49,587 base 152 Not Found: /authorizations/
WARNING 2019-09-11 01:24:49,587 basehttp 124 "POST /authorizations/ HTTP/1.1" 404 2716
INFO 2019-09-11 01:27:07,307 basehttp 124 "GET /usernames/changyu/count/ HTTP/1.1" 200 11
INFO 2019-09-11 01:27:20,041 basehttp 124 "GET /mobiles/17310115251/count/ HTTP/1.1" 200 11
INFO 2019-09-11 01:27:20,283 basehttp 124 "GET /mobiles/17310115251/count/ HTTP/1.1" 200 11
INFO 2019-09-11 01:27:20,326 basehttp 124 "GET /sms_codes/17310115251/ HTTP/1.1" 200 4
INFO 2019-09-11 01:27:32,766 basehttp 124 "GET /usernames/changyu/count/ HTTP/1.1" 200 11
INFO 2019-09-11 01:27:32,777 basehttp 124 "GET /mobiles/17310115251/count/ HTTP/1.1" 200 11
INFO 2019-09-11 01:27:32,779 basehttp 124 "OPTIONS /users/ HTTP/1.1" 200 0
INFO 2019-09-11 01:27:32,838 basehttp 124 "POST /users/ HTTP/1.1" 201 109
WARNING 2019-09-11 01:27:32,973 base 152 Not Found: /skus/search/
WARNING 2019-09-11 01:27:32,976 basehttp 124 "GET /skus/search/?page=1&page_size=6 HTTP/1.1" 404 2729
WARNING 2019-09-11 01:28:57,266 base 152 Not Found: /skus/search/
WARNING 2019-09-11 01:28:57,268 basehttp 124 "GET /skus/search/?page=1&page_size=6 HTTP/1.1" 404 2729
INFO 2019-09-11 01:29:02,353 basehttp 124 "OPTIONS /authorizations/ HTTP/1.1" 200 0
WARNING 2019-09-11 01:29:02,361 base 152 Not Found: /authorizations/
WARNING 2019-09-11 01:29:02,361 basehttp 124 "POST /authorizations/ HTTP/1.1" 404 2716
INFO 2019-09-11 01:29:07,035 basehttp 124 "GET /usernames/changyu/count/ HTTP/1.1" 200 11
INFO 2019-09-11 01:29:11,388 basehttp 124 "GET /usernames/liudehua/count/ HTTP/1.1" 200 11
INFO 2019-09-11 01:29:22,748 basehttp 124 "GET /mobiles/18888888888/count/ HTTP/1.1" 200 11
INFO 2019-09-11 01:29:22,997 basehttp 124 "GET /mobiles/18888888888/count/ HTTP/1.1" 200 11
INFO 2019-09-11 01:29:23,029 basehttp 124 "GET /sms_codes/18888888888/ HTTP/1.1" 200 4
INFO 2019-09-11 01:29:49,212 basehttp 124 "GET /usernames/liudehua/count/ HTTP/1.1" 200 11
INFO 2019-09-11 01:29:49,218 basehttp 124 "GET /mobiles/18888888888/count/ HTTP/1.1" 200 11
ERROR 2019-09-11 01:29:49,227 exceptions 25 [<users.views.UserView object at 0x7f04f1dd4710>] (1062, "Duplicate entry '' for key 'mobile'")
ERROR 2019-09-11 01:29:49,230 basehttp 124 "POST /users/ HTTP/1.1" 507 35
ERROR 2019-09-11 01:29:51,375 exceptions 25 [<users.views.UserView object at 0x7f04f1e01da0>] (1062, "Duplicate entry '' for key 'mobile'")
ERROR 2019-09-11 01:29:51,376 basehttp 124 "POST /users/ HTTP/1.1" 507 35
INFO 2019-09-11 01:29:51,386 basehttp 124 "GET /mobiles/18888888888/count/ HTTP/1.1" 200 11
INFO 2019-09-11 01:29:51,388 basehttp 124 "GET /usernames/liudehua/count/ HTTP/1.1" 200 11
INFO 2019-09-11 01:30:00,519 basehttp 124 "GET /mobiles/18888888888/count/ HTTP/1.1" 200 11
INFO 2019-09-11 01:30:30,346 basehttp 124 "GET /mobiles/17388888888/count/ HTTP/1.1" 200 11
INFO 2019-09-11 01:30:30,531 basehttp 124 "GET /sms_codes/17388888888/ HTTP/1.1" 200 4
INFO 2019-09-11 01:30:30,557 basehttp 124 "GET /mobiles/17388888888/count/ HTTP/1.1" 200 11
INFO 2019-09-11 01:30:46,339 basehttp 124 "GET /usernames/liudehua/count/ HTTP/1.1" 200 11
INFO 2019-09-11 01:30:46,340 basehttp 124 "GET /mobiles/17388888888/count/ HTTP/1.1" 200 11
ERROR 2019-09-11 01:30:46,356 exceptions 25 [<users.views.UserView object at 0x7f04f15add30>] (1062, "Duplicate entry '' for key 'mobile'")
ERROR 2019-09-11 01:30:46,357 basehttp 124 "POST /users/ HTTP/1.1" 507 35
INFO 2019-09-11 11:14:32,486 basehttp 124 "GET /usernames/changyu/count/ HTTP/1.1" 200 11
INFO 2019-09-11 11:14:38,679 basehttp 124 "GET /usernames/zhangmingyue/count/ HTTP/1.1" 200 11
INFO 2019-09-11 11:14:55,827 basehttp 124 "GET /mobiles/17312121212/count/ HTTP/1.1" 200 11
INFO 2019-09-11 11:14:56,074 basehttp 124 "GET /mobiles/17312121212/count/ HTTP/1.1" 200 11
INFO 2019-09-11 11:14:56,107 basehttp 124 "GET /sms_codes/17312121212/ HTTP/1.1" 200 4
INFO 2019-09-11 11:15:12,015 basehttp 124 "GET /usernames/zhangmingyue/count/ HTTP/1.1" 200 11
INFO 2019-09-11 11:15:12,022 basehttp 124 "GET /mobiles/17312121212/count/ HTTP/1.1" 200 11
ERROR 2019-09-11 11:15:12,027 exceptions 25 [<users.views.UserView object at 0x7f433e0cb898>] (1062, "Duplicate entry '' for key 'mobile'")
ERROR 2019-09-11 11:15:12,028 basehttp 124 "POST /users/ HTTP/1.1" 507 35
INFO 2019-09-11 11:17:59,558 basehttp 124 "GET /usernames/changyu/count/ HTTP/1.1" 200 11
INFO 2019-09-11 11:18:06,231 basehttp 124 "GET /usernames/zhangmingyue/count/ HTTP/1.1" 200 11
INFO 2019-09-11 11:18:16,760 basehttp 124 "GET /mobiles/17312121212/count/ HTTP/1.1" 200 11
INFO 2019-09-11 11:18:18,678 basehttp 124 "GET /mobiles/17312121212/count/ HTTP/1.1" 200 11
INFO 2019-09-11 11:18:18,722 basehttp 124 "GET /sms_codes/17312121212/ HTTP/1.1" 200 4
INFO 2019-09-11 11:18:38,026 basehttp 124 "GET /usernames/zhangmingyue/count/ HTTP/1.1" 200 11
INFO 2019-09-11 11:18:38,028 basehttp 124 "GET /mobiles/17312121212/count/ HTTP/1.1" 200 11
ERROR 2019-09-11 11:20:15,587 exceptions 25 [<users.views.UserView object at 0x7fe5aa0a5cf8>] (1062, "Duplicate entry '' for key 'mobile'")
ERROR 2019-09-11 11:21:11,248 basehttp 124 "POST /users/ HTTP/1.1" 507 35
INFO 2019-09-11 11:21:19,054 basehttp 124 "GET /usernames/zhangmingyue/count/ HTTP/1.1" 200 11
INFO 2019-09-11 11:21:19,065 basehttp 124 "GET /mobiles/17312121212/count/ HTTP/1.1" 200 11
INFO 2019-09-11 11:21:36,772 basehttp 124 "GET /usernames/changyu/count/ HTTP/1.1" 200 11
INFO 2019-09-11 11:21:39,197 basehttp 124 "GET /usernames/mingyue/count/ HTTP/1.1" 200 11
INFO 2019-09-11 11:22:05,712 basehttp 124 "GET /mobiles/17369595959/count/ HTTP/1.1" 200 11
INFO 2019-09-11 11:22:05,944 basehttp 124 "GET /mobiles/17369595959/count/ HTTP/1.1" 200 11
INFO 2019-09-11 11:22:05,988 basehttp 124 "GET /sms_codes/17369595959/ HTTP/1.1" 200 4
INFO 2019-09-11 11:22:28,469 basehttp 124 "GET /mobiles/17369595959/count/ HTTP/1.1" 200 11
ERROR 2019-09-11 11:22:28,487 exceptions 25 [<users.views.UserView object at 0x7f12277816d8>] (1062, "Duplicate entry '' for key 'mobile'")
ERROR 2019-09-11 11:22:28,490 basehttp 124 "POST /users/ HTTP/1.1" 507 35
INFO 2019-09-11 11:22:28,494 basehttp 124 "GET /usernames/mingyue/count/ HTTP/1.1" 200 11
INFO 2019-09-11 11:22:30,449 basehttp 124 "GET /mobiles/17369595959/count/ HTTP/1.1" 200 11
INFO 2019-09-11 11:22:30,453 basehttp 124 "GET /usernames/mingyue/count/ HTTP/1.1" 200 11
ERROR 2019-09-11 11:22:30,460 exceptions 25 [<users.views.UserView object at 0x7f1226f7d668>] (1062, "Duplicate entry '' for key 'mobile'")
ERROR 2019-09-11 11:22:30,461 basehttp 124 "POST /users/ HTTP/1.1" 507 35
INFO 2019-09-11 11:22:31,944 basehttp 124 "GET /mobiles/17369595959/count/ HTTP/1.1" 200 11
INFO 2019-09-11 11:22:31,947 basehttp 124 "GET /usernames/mingyue/count/ HTTP/1.1" 200 11
ERROR 2019-09-11 11:22:31,957 exceptions 25 [<users.views.UserView object at 0x7f1226f6def0>] (1062, "Duplicate entry '' for key 'mobile'")
ERROR 2019-09-11 11:22:31,958 basehttp 124 "POST /users/ HTTP/1.1" 507 35
INFO 2019-09-11 11:38:04,437 basehttp 124 "GET /usernames/changyu/count/ HTTP/1.1" 200 11
INFO 2019-09-11 11:38:09,694 basehttp 124 "GET /usernames/zhangmingyue/count/ HTTP/1.1" 200 11
INFO 2019-09-11 11:38:25,869 basehttp 124 "GET /mobiles/17351515151/count/ HTTP/1.1" 200 11
INFO 2019-09-11 11:38:26,125 basehttp 124 "GET /mobiles/17351515151/count/ HTTP/1.1" 200 11
INFO 2019-09-11 11:38:26,149 basehttp 124 "GET /sms_codes/17351515151/ HTTP/1.1" 200 4
INFO 2019-09-11 11:38:40,955 basehttp 124 "GET /mobiles/17351515151/count/ HTTP/1.1" 200 11
INFO 2019-09-11 11:38:40,959 basehttp 124 "GET /usernames/zhangmingyue/count/ HTTP/1.1" 200 11
INFO 2019-09-11 11:38:40,998 basehttp 124 "POST /users/ HTTP/1.1" 201 58
WARNING 2019-09-11 11:38:41,115 base 152 Not Found: /skus/search/
WARNING 2019-09-11 11:38:41,116 basehttp 124 "GET /skus/search/?page=1&page_size=6 HTTP/1.1" 404 2729
WARNING 2019-09-11 11:42:53,475 base 152 Not Found: /skus/search/
WARNING 2019-09-11 11:42:53,475 basehttp 124 "GET /skus/search/?page=1&page_size=6 HTTP/1.1" 404 2729
INFO 2019-09-11 17:00:23,690 basehttp 124 "GET /usernames/wangchangyu/count/ HTTP/1.1" 200 11
INFO 2019-09-11 17:00:43,815 basehttp 124 "GET /mobiles/17310116666/count/ HTTP/1.1" 200 11
INFO 2019-09-11 17:00:44,050 basehttp 124 "GET /mobiles/17310116666/count/ HTTP/1.1" 200 11
INFO 2019-09-11 17:00:44,126 basehttp 124 "GET /sms_codes/17310116666/ HTTP/1.1" 200 4
INFO 2019-09-11 17:01:01,403 basehttp 124 "OPTIONS /users/ HTTP/1.1" 200 0
INFO 2019-09-11 17:01:01,415 basehttp 124 "GET /mobiles/17310116666/count/ HTTP/1.1" 200 11
INFO 2019-09-11 17:01:01,419 basehttp 124 "GET /usernames/wangchangyu/count/ HTTP/1.1" 200 11
INFO 2019-09-11 17:01:01,459 basehttp 124 "POST /users/ HTTP/1.1" 201 239
INFO 2019-09-11 17:20:20,339 basehttp 124 "OPTIONS /authorizations/ HTTP/1.1" 200 0
WARNING 2019-09-11 17:20:20,380 base 152 Not Found: /authorizations/
WARNING 2019-09-11 17:20:20,381 basehttp 124 "POST /authorizations/ HTTP/1.1" 404 2880
WARNING 2019-09-11 17:20:29,801 base 152 Not Found: /authorizations/
WARNING 2019-09-11 17:20:29,803 basehttp 124 "POST /authorizations/ HTTP/1.1" 404 2880
WARNING 2019-09-11 17:20:59,640 base 152 Not Found: /authorizations/
WARNING 2019-09-11 17:20:59,640 basehttp 124 "POST /authorizations/ HTTP/1.1" 404 2880
WARNING 2019-09-11 17:21:32,078 base 152 Not Found: /authorizations/
WARNING 2019-09-11 17:21:32,079 basehttp 124 "POST /authorizations/ HTTP/1.1" 404 2880
WARNING 2019-09-11 17:24:26,382 basehttp 124 "POST /authorizations/ HTTP/1.1" 400 67
INFO 2019-09-11 17:24:43,941 basehttp 124 "POST /authorizations/ HTTP/1.1" 200 183
INFO 2019-09-11 22:08:40,640 basehttp 124 "OPTIONS /authorizations/ HTTP/1.1" 200 0
INFO 2019-09-11 22:08:40,803 basehttp 124 "POST /authorizations/ HTTP/1.1" 200 221
INFO 2019-09-12 09:44:23,464 basehttp 124 "GET /usernames/changyu/count/ HTTP/1.1" 200 11
INFO 2019-09-12 09:44:32,624 basehttp 124 "GET /usernames/13911111111/count/ HTTP/1.1" 200 11
INFO 2019-09-12 09:44:51,365 basehttp 124 "GET /mobiles/13911111111/count/ HTTP/1.1" 200 11
INFO 2019-09-12 09:44:51,594 basehttp 124 "GET /mobiles/13911111111/count/ HTTP/1.1" 200 11
INFO 2019-09-12 09:44:51,643 basehttp 124 "GET /sms_codes/13911111111/ HTTP/1.1" 200 4
INFO 2019-09-12 09:45:32,416 basehttp 124 "OPTIONS /users/ HTTP/1.1" 200 0
INFO 2019-09-12 09:45:32,432 basehttp 124 "GET /usernames/13911111111/count/ HTTP/1.1" 200 11
INFO 2019-09-12 09:45:32,437 basehttp 124 "GET /mobiles/13911111111/count/ HTTP/1.1" 200 11
INFO 2019-09-12 09:45:32,481 basehttp 124 "POST /users/ HTTP/1.1" 201 239
INFO 2019-09-12 09:45:41,485 basehttp 124 "GET /usernames/changyu/count/ HTTP/1.1" 200 11
INFO 2019-09-12 09:45:47,709 basehttp 124 "GET /usernames/13811111111/count/ HTTP/1.1" 200 11
INFO 2019-09-12 09:46:08,419 basehttp 124 "GET /mobiles/13821111111/count/ HTTP/1.1" 200 11
INFO 2019-09-12 09:46:08,614 basehttp 124 "GET /sms_codes/13821111111/ HTTP/1.1" 200 4
INFO 2019-09-12 09:46:08,627 basehttp 124 "GET /mobiles/13821111111/count/ HTTP/1.1" 200 11
INFO 2019-09-12 09:46:22,927 basehttp 124 "GET /mobiles/13821111111/count/ HTTP/1.1" 200 11
INFO 2019-09-12 09:46:22,932 basehttp 124 "GET /usernames/13811111111/count/ HTTP/1.1" 200 11
WARNING 2019-09-12 09:46:22,935 basehttp 124 "POST /users/ HTTP/1.1" 400 55
WARNING 2019-09-12 13:54:07,610 base 152 Not Found: /oauth/qq/authorization/
WARNING 2019-09-12 13:54:07,612 basehttp 124 "GET /oauth/qq/authorization/?next=/ HTTP/1.1" 404 3017
WARNING 2019-09-12 13:54:12,845 base 152 Not Found: /oauth/qq/authorization/
WARNING 2019-09-12 13:54:12,847 basehttp 124 "GET /oauth/qq/authorization/?next=/ HTTP/1.1" 404 3017
WARNING 2019-09-12 13:54:16,127 base 152 Not Found: /oauth/qq/authorization/
WARNING 2019-09-12 13:54:16,128 basehttp 124 "GET /oauth/qq/authorization/?next=/ HTTP/1.1" 404 3017
WARNING 2019-09-12 13:54:17,113 base 152 Not Found: /oauth/qq/authorization/
WARNING 2019-09-12 13:54:17,113 basehttp 124 "GET /oauth/qq/authorization/?next=/ HTTP/1.1" 404 3017
WARNING 2019-09-12 13:56:02,070 base 152 Not Found: /oauth/qq/authorization/
WARNING 2019-09-12 13:56:02,071 basehttp 124 "GET /oauth/qq/authorization/?next=/ HTTP/1.1" 404 3017
WARNING 2019-09-12 13:56:04,189 base 152 Not Found: /oauth/qq/authorization/
WARNING 2019-09-12 13:56:04,190 basehttp 124 "GET /oauth/qq/authorization/?next=/ HTTP/1.1" 404 3017
WARNING 2019-09-12 13:56:04,754 base 152 Not Found: /oauth/qq/authorization/
WARNING 2019-09-12 13:56:04,754 basehttp 124 "GET /oauth/qq/authorization/?next=/ HTTP/1.1" 404 3017
ERROR 2019-09-12 13:59:43,007 exception 135 Internal Server Error: /oauth/qq/authorization/
Traceback (most recent call last):
  File "/home/changle-lab/.virtualenvs/shoppingMall/lib/python3.6/site-packages/rest_framework/request.py", line 411, in __getattr__
    return getattr(self._request, attr)
AttributeError: 'WSGIRequest' object has no attribute 'query_paramas'

During handling of the above exception, another exception occurred:

Traceback (most recent call last):
  File "/home/changle-lab/.virtualenvs/shoppingMall/lib/python3.6/site-packages/django/core/handlers/exception.py", line 41, in inner
    response = get_response(request)
  File "/home/changle-lab/.virtualenvs/shoppingMall/lib/python3.6/site-packages/django/core/handlers/base.py", line 187, in _get_response
    response = self.process_exception_by_middleware(e, request)
  File "/home/changle-lab/.virtualenvs/shoppingMall/lib/python3.6/site-packages/django/core/handlers/base.py", line 185, in _get_response
    response = wrapped_callback(request, *callback_args, **callback_kwargs)
  File "/home/changle-lab/.virtualenvs/shoppingMall/lib/python3.6/site-packages/django/views/decorators/csrf.py", line 58, in wrapped_view
    return view_func(*args, **kwargs)
  File "/home/changle-lab/.virtualenvs/shoppingMall/lib/python3.6/site-packages/django/views/generic/base.py", line 68, in view
    return self.dispatch(request, *args, **kwargs)
  File "/home/changle-lab/.virtualenvs/shoppingMall/lib/python3.6/site-packages/rest_framework/views.py", line 483, in dispatch
    response = self.handle_exception(exc)
  File "/home/changle-lab/.virtualenvs/shoppingMall/lib/python3.6/site-packages/rest_framework/views.py", line 443, in handle_exception
    self.raise_uncaught_exception(exc)
  File "/home/changle-lab/.virtualenvs/shoppingMall/lib/python3.6/site-packages/rest_framework/views.py", line 480, in dispatch
    response = handler(request, *args, **kwargs)
  File "/home/changle-lab/Desktop/shopping_mall/shoppingMall/meiduo_mall/meiduo_mall/apps/oauth/views.py", line 17, in get
    state = request.query_paramas.get('next')
  File "/home/changle-lab/.virtualenvs/shoppingMall/lib/python3.6/site-packages/rest_framework/request.py", line 413, in __getattr__
    return self.__getattribute__(attr)
AttributeError: 'Request' object has no attribute 'query_paramas'
ERROR 2019-09-12 13:59:43,058 basehttp 124 "GET /oauth/qq/authorization/?next=/ HTTP/1.1" 500 19577
ERROR 2019-09-12 13:59:45,238 exception 135 Internal Server Error: /oauth/qq/authorization/
Traceback (most recent call last):
  File "/home/changle-lab/.virtualenvs/shoppingMall/lib/python3.6/site-packages/rest_framework/request.py", line 411, in __getattr__
    return getattr(self._request, attr)
AttributeError: 'WSGIRequest' object has no attribute 'query_paramas'

During handling of the above exception, another exception occurred:

Traceback (most recent call last):
  File "/home/changle-lab/.virtualenvs/shoppingMall/lib/python3.6/site-packages/django/core/handlers/exception.py", line 41, in inner
    response = get_response(request)
  File "/home/changle-lab/.virtualenvs/shoppingMall/lib/python3.6/site-packages/django/core/handlers/base.py", line 187, in _get_response
    response = self.process_exception_by_middleware(e, request)
  File "/home/changle-lab/.virtualenvs/shoppingMall/lib/python3.6/site-packages/django/core/handlers/base.py", line 185, in _get_response
    response = wrapped_callback(request, *callback_args, **callback_kwargs)
  File "/home/changle-lab/.virtualenvs/shoppingMall/lib/python3.6/site-packages/django/views/decorators/csrf.py", line 58, in wrapped_view
    return view_func(*args, **kwargs)
  File "/home/changle-lab/.virtualenvs/shoppingMall/lib/python3.6/site-packages/django/views/generic/base.py", line 68, in view
    return self.dispatch(request, *args, **kwargs)
  File "/home/changle-lab/.virtualenvs/shoppingMall/lib/python3.6/site-packages/rest_framework/views.py", line 483, in dispatch
    response = self.handle_exception(exc)
  File "/home/changle-lab/.virtualenvs/shoppingMall/lib/python3.6/site-packages/rest_framework/views.py", line 443, in handle_exception
    self.raise_uncaught_exception(exc)
  File "/home/changle-lab/.virtualenvs/shoppingMall/lib/python3.6/site-packages/rest_framework/views.py", line 480, in dispatch
    response = handler(request, *args, **kwargs)
  File "/home/changle-lab/Desktop/shopping_mall/shoppingMall/meiduo_mall/meiduo_mall/apps/oauth/views.py", line 17, in get
    state = request.query_paramas.get('next')
  File "/home/changle-lab/.virtualenvs/shoppingMall/lib/python3.6/site-packages/rest_framework/request.py", line 413, in __getattr__
    return self.__getattribute__(attr)
AttributeError: 'Request' object has no attribute 'query_paramas'
ERROR 2019-09-12 13:59:45,269 basehttp 124 "GET /oauth/qq/authorization/?next=/ HTTP/1.1" 500 19577
ERROR 2019-09-12 14:00:10,429 exception 135 Internal Server Error: /oauth/qq/authorization/
Traceback (most recent call last):
  File "/home/changle-lab/.virtualenvs/shoppingMall/lib/python3.6/site-packages/django/core/handlers/exception.py", line 41, in inner
    response = get_response(request)
  File "/home/changle-lab/.virtualenvs/shoppingMall/lib/python3.6/site-packages/django/core/handlers/base.py", line 187, in _get_response
    response = self.process_exception_by_middleware(e, request)
  File "/home/changle-lab/.virtualenvs/shoppingMall/lib/python3.6/site-packages/django/core/handlers/base.py", line 185, in _get_response
    response = wrapped_callback(request, *callback_args, **callback_kwargs)
  File "/home/changle-lab/.virtualenvs/shoppingMall/lib/python3.6/site-packages/django/views/decorators/csrf.py", line 58, in wrapped_view
    return view_func(*args, **kwargs)
  File "/home/changle-lab/.virtualenvs/shoppingMall/lib/python3.6/site-packages/django/views/generic/base.py", line 68, in view
    return self.dispatch(request, *args, **kwargs)
  File "/home/changle-lab/.virtualenvs/shoppingMall/lib/python3.6/site-packages/rest_framework/views.py", line 483, in dispatch
    response = self.handle_exception(exc)
  File "/home/changle-lab/.virtualenvs/shoppingMall/lib/python3.6/site-packages/rest_framework/views.py", line 443, in handle_exception
    self.raise_uncaught_exception(exc)
  File "/home/changle-lab/.virtualenvs/shoppingMall/lib/python3.6/site-packages/rest_framework/views.py", line 480, in dispatch
    response = handler(request, *args, **kwargs)
  File "/home/changle-lab/Desktop/shopping_mall/shoppingMall/meiduo_mall/meiduo_mall/apps/oauth/views.py", line 29, in get
    return Response({'login_url': login_url})
TypeError: __init__() takes 1 positional argument but 2 were given
ERROR 2019-09-12 14:00:10,455 basehttp 124 "GET /oauth/qq/authorization/?next=/ HTTP/1.1" 500 19082
ERROR 2019-09-12 14:02:21,036 exception 135 Internal Server Error: /oauth/qq/authorization/
Traceback (most recent call last):
  File "/home/changle-lab/.virtualenvs/shoppingMall/lib/python3.6/site-packages/django/core/handlers/exception.py", line 41, in inner
    response = get_response(request)
  File "/home/changle-lab/.virtualenvs/shoppingMall/lib/python3.6/site-packages/django/core/handlers/base.py", line 187, in _get_response
    response = self.process_exception_by_middleware(e, request)
  File "/home/changle-lab/.virtualenvs/shoppingMall/lib/python3.6/site-packages/django/core/handlers/base.py", line 185, in _get_response
    response = wrapped_callback(request, *callback_args, **callback_kwargs)
  File "/home/changle-lab/.virtualenvs/shoppingMall/lib/python3.6/site-packages/django/views/decorators/csrf.py", line 58, in wrapped_view
    return view_func(*args, **kwargs)
  File "/home/changle-lab/.virtualenvs/shoppingMall/lib/python3.6/site-packages/django/views/generic/base.py", line 68, in view
    return self.dispatch(request, *args, **kwargs)
  File "/home/changle-lab/.virtualenvs/shoppingMall/lib/python3.6/site-packages/rest_framework/views.py", line 483, in dispatch
    response = self.handle_exception(exc)
  File "/home/changle-lab/.virtualenvs/shoppingMall/lib/python3.6/site-packages/rest_framework/views.py", line 443, in handle_exception
    self.raise_uncaught_exception(exc)
  File "/home/changle-lab/.virtualenvs/shoppingMall/lib/python3.6/site-packages/rest_framework/views.py", line 480, in dispatch
    response = handler(request, *args, **kwargs)
  File "/home/changle-lab/Desktop/shopping_mall/shoppingMall/meiduo_mall/meiduo_mall/apps/oauth/views.py", line 28, in get
    return Response({'login_url': login_url})
TypeError: __init__() takes 1 positional argument but 2 were given
ERROR 2019-09-12 14:02:21,063 basehttp 124 "GET /oauth/qq/authorization/?next=/ HTTP/1.1" 500 19082
ERROR 2019-09-12 14:04:44,534 exception 135 Internal Server Error: /oauth/qq/authorization/
Traceback (most recent call last):
  File "/home/changle-lab/.virtualenvs/shoppingMall/lib/python3.6/site-packages/django/core/handlers/exception.py", line 41, in inner
    response = get_response(request)
  File "/home/changle-lab/.virtualenvs/shoppingMall/lib/python3.6/site-packages/django/core/handlers/base.py", line 187, in _get_response
    response = self.process_exception_by_middleware(e, request)
  File "/home/changle-lab/.virtualenvs/shoppingMall/lib/python3.6/site-packages/django/core/handlers/base.py", line 185, in _get_response
    response = wrapped_callback(request, *callback_args, **callback_kwargs)
  File "/home/changle-lab/.virtualenvs/shoppingMall/lib/python3.6/site-packages/django/views/decorators/csrf.py", line 58, in wrapped_view
    return view_func(*args, **kwargs)
  File "/home/changle-lab/.virtualenvs/shoppingMall/lib/python3.6/site-packages/django/views/generic/base.py", line 68, in view
    return self.dispatch(request, *args, **kwargs)
  File "/home/changle-lab/.virtualenvs/shoppingMall/lib/python3.6/site-packages/rest_framework/views.py", line 483, in dispatch
    response = self.handle_exception(exc)
  File "/home/changle-lab/.virtualenvs/shoppingMall/lib/python3.6/site-packages/rest_framework/views.py", line 443, in handle_exception
    self.raise_uncaught_exception(exc)
  File "/home/changle-lab/.virtualenvs/shoppingMall/lib/python3.6/site-packages/rest_framework/views.py", line 480, in dispatch
    response = handler(request, *args, **kwargs)
  File "/home/changle-lab/Desktop/shopping_mall/shoppingMall/meiduo_mall/meiduo_mall/apps/oauth/views.py", line 30, in get
    return Response({'login_url': login_url})
TypeError: __init__() takes 1 positional argument but 2 were given
ERROR 2019-09-12 14:04:44,562 basehttp 124 "GET /oauth/qq/authorization/?next=/ HTTP/1.1" 500 19082
ERROR 2019-09-12 14:11:03,082 exception 135 Internal Server Error: /oauth/qq/authorization/
Traceback (most recent call last):
  File "/home/changle-lab/.virtualenvs/shoppingMall/lib/python3.6/site-packages/django/core/handlers/exception.py", line 41, in inner
    response = get_response(request)
  File "/home/changle-lab/.virtualenvs/shoppingMall/lib/python3.6/site-packages/django/core/handlers/base.py", line 187, in _get_response
    response = self.process_exception_by_middleware(e, request)
  File "/home/changle-lab/.virtualenvs/shoppingMall/lib/python3.6/site-packages/django/core/handlers/base.py", line 185, in _get_response
    response = wrapped_callback(request, *callback_args, **callback_kwargs)
  File "/home/changle-lab/.virtualenvs/shoppingMall/lib/python3.6/site-packages/django/views/decorators/csrf.py", line 58, in wrapped_view
    return view_func(*args, **kwargs)
  File "/home/changle-lab/.virtualenvs/shoppingMall/lib/python3.6/site-packages/django/views/generic/base.py", line 68, in view
    return self.dispatch(request, *args, **kwargs)
  File "/home/changle-lab/.virtualenvs/shoppingMall/lib/python3.6/site-packages/rest_framework/views.py", line 483, in dispatch
    response = self.handle_exception(exc)
  File "/home/changle-lab/.virtualenvs/shoppingMall/lib/python3.6/site-packages/rest_framework/views.py", line 443, in handle_exception
    self.raise_uncaught_exception(exc)
  File "/home/changle-lab/.virtualenvs/shoppingMall/lib/python3.6/site-packages/rest_framework/views.py", line 480, in dispatch
    response = handler(request, *args, **kwargs)
  File "/home/changle-lab/Desktop/shopping_mall/shoppingMall/meiduo_mall/meiduo_mall/apps/oauth/views.py", line 24, in get
    next=next)
TypeError: __init__() got an unexpected keyword argument 'next'
ERROR 2019-09-12 14:11:03,134 basehttp 124 "GET /oauth/qq/authorization/?next=/ HTTP/1.1" 500 19058
ERROR 2019-09-12 14:12:28,329 exception 135 Internal Server Error: /oauth/qq/authorization/
Traceback (most recent call last):
  File "/home/changle-lab/.virtualenvs/shoppingMall/lib/python3.6/site-packages/django/core/handlers/exception.py", line 41, in inner
    response = get_response(request)
  File "/home/changle-lab/.virtualenvs/shoppingMall/lib/python3.6/site-packages/django/core/handlers/base.py", line 187, in _get_response
    response = self.process_exception_by_middleware(e, request)
  File "/home/changle-lab/.virtualenvs/shoppingMall/lib/python3.6/site-packages/django/core/handlers/base.py", line 185, in _get_response
    response = wrapped_callback(request, *callback_args, **callback_kwargs)
  File "/home/changle-lab/.virtualenvs/shoppingMall/lib/python3.6/site-packages/django/views/decorators/csrf.py", line 58, in wrapped_view
    return view_func(*args, **kwargs)
  File "/home/changle-lab/.virtualenvs/shoppingMall/lib/python3.6/site-packages/django/views/generic/base.py", line 68, in view
    return self.dispatch(request, *args, **kwargs)
  File "/home/changle-lab/.virtualenvs/shoppingMall/lib/python3.6/site-packages/rest_framework/views.py", line 483, in dispatch
    response = self.handle_exception(exc)
  File "/home/changle-lab/.virtualenvs/shoppingMall/lib/python3.6/site-packages/rest_framework/views.py", line 443, in handle_exception
    self.raise_uncaught_exception(exc)
  File "/home/changle-lab/.virtualenvs/shoppingMall/lib/python3.6/site-packages/rest_framework/views.py", line 480, in dispatch
    response = handler(request, *args, **kwargs)
  File "/home/changle-lab/Desktop/shopping_mall/shoppingMall/meiduo_mall/meiduo_mall/apps/oauth/views.py", line 31, in get
    return Response({'login_url': login_url})
TypeError: __init__() takes 1 positional argument but 2 were given
ERROR 2019-09-12 14:12:28,360 basehttp 124 "GET /oauth/qq/authorization/?next=/ HTTP/1.1" 500 19082
ERROR 2019-09-12 14:13:01,549 exception 135 Internal Server Error: /oauth/qq/authorization/
Traceback (most recent call last):
  File "/home/changle-lab/.virtualenvs/shoppingMall/lib/python3.6/site-packages/django/core/handlers/exception.py", line 41, in inner
    response = get_response(request)
  File "/home/changle-lab/.virtualenvs/shoppingMall/lib/python3.6/site-packages/django/core/handlers/base.py", line 187, in _get_response
    response = self.process_exception_by_middleware(e, request)
  File "/home/changle-lab/.virtualenvs/shoppingMall/lib/python3.6/site-packages/django/core/handlers/base.py", line 185, in _get_response
    response = wrapped_callback(request, *callback_args, **callback_kwargs)
  File "/home/changle-lab/.virtualenvs/shoppingMall/lib/python3.6/site-packages/django/views/decorators/csrf.py", line 58, in wrapped_view
    return view_func(*args, **kwargs)
  File "/home/changle-lab/.virtualenvs/shoppingMall/lib/python3.6/site-packages/django/views/generic/base.py", line 68, in view
    return self.dispatch(request, *args, **kwargs)
  File "/home/changle-lab/.virtualenvs/shoppingMall/lib/python3.6/site-packages/rest_framework/views.py", line 483, in dispatch
    response = self.handle_exception(exc)
  File "/home/changle-lab/.virtualenvs/shoppingMall/lib/python3.6/site-packages/rest_framework/views.py", line 443, in handle_exception
    self.raise_uncaught_exception(exc)
  File "/home/changle-lab/.virtualenvs/shoppingMall/lib/python3.6/site-packages/rest_framework/views.py", line 480, in dispatch
    response = handler(request, *args, **kwargs)
  File "/home/changle-lab/Desktop/shopping_mall/shoppingMall/meiduo_mall/meiduo_mall/apps/oauth/views.py", line 31, in get
    return Response({'login_url': login_url})
TypeError: __init__() takes 1 positional argument but 2 were given
ERROR 2019-09-12 14:13:01,575 basehttp 124 "GET /oauth/qq/authorization/?next=/ HTTP/1.1" 500 19082
ERROR 2019-09-12 14:21:48,432 exception 135 Internal Server Error: /oauth/qq/authorization/
Traceback (most recent call last):
  File "/home/changle-lab/.virtualenvs/shoppingMall/lib/python3.6/site-packages/django/core/handlers/exception.py", line 41, in inner
    response = get_response(request)
  File "/home/changle-lab/.virtualenvs/shoppingMall/lib/python3.6/site-packages/django/core/handlers/base.py", line 187, in _get_response
    response = self.process_exception_by_middleware(e, request)
  File "/home/changle-lab/.virtualenvs/shoppingMall/lib/python3.6/site-packages/django/core/handlers/base.py", line 185, in _get_response
    response = wrapped_callback(request, *callback_args, **callback_kwargs)
  File "/home/changle-lab/.virtualenvs/shoppingMall/lib/python3.6/site-packages/django/views/decorators/csrf.py", line 58, in wrapped_view
    return view_func(*args, **kwargs)
  File "/home/changle-lab/.virtualenvs/shoppingMall/lib/python3.6/site-packages/django/views/generic/base.py", line 68, in view
    return self.dispatch(request, *args, **kwargs)
  File "/home/changle-lab/.virtualenvs/shoppingMall/lib/python3.6/site-packages/rest_framework/views.py", line 483, in dispatch
    response = self.handle_exception(exc)
  File "/home/changle-lab/.virtualenvs/shoppingMall/lib/python3.6/site-packages/rest_framework/views.py", line 443, in handle_exception
    self.raise_uncaught_exception(exc)
  File "/home/changle-lab/.virtualenvs/shoppingMall/lib/python3.6/site-packages/rest_framework/views.py", line 480, in dispatch
    response = handler(request, *args, **kwargs)
  File "/home/changle-lab/Desktop/shopping_mall/shoppingMall/meiduo_mall/meiduo_mall/apps/oauth/views.py", line 48, in get
    return Response({'login_url':login_url})
TypeError: __init__() takes 1 positional argument but 2 were given
ERROR 2019-09-12 14:21:48,462 basehttp 124 "GET /oauth/qq/authorization/?next=/ HTTP/1.1" 500 19081
ERROR 2019-09-12 14:25:03,622 exception 135 Internal Server Error: /oauth/qq/authorization/
Traceback (most recent call last):
  File "/home/changle-lab/.virtualenvs/shoppingMall/lib/python3.6/site-packages/django/core/handlers/exception.py", line 41, in inner
    response = get_response(request)
  File "/home/changle-lab/.virtualenvs/shoppingMall/lib/python3.6/site-packages/django/core/handlers/base.py", line 187, in _get_response
    response = self.process_exception_by_middleware(e, request)
  File "/home/changle-lab/.virtualenvs/shoppingMall/lib/python3.6/site-packages/django/core/handlers/base.py", line 185, in _get_response
    response = wrapped_callback(request, *callback_args, **callback_kwargs)
  File "/home/changle-lab/.virtualenvs/shoppingMall/lib/python3.6/site-packages/django/views/decorators/csrf.py", line 58, in wrapped_view
    return view_func(*args, **kwargs)
  File "/home/changle-lab/.virtualenvs/shoppingMall/lib/python3.6/site-packages/django/views/generic/base.py", line 68, in view
    return self.dispatch(request, *args, **kwargs)
  File "/home/changle-lab/.virtualenvs/shoppingMall/lib/python3.6/site-packages/rest_framework/views.py", line 483, in dispatch
    response = self.handle_exception(exc)
  File "/home/changle-lab/.virtualenvs/shoppingMall/lib/python3.6/site-packages/rest_framework/views.py", line 443, in handle_exception
    self.raise_uncaught_exception(exc)
  File "/home/changle-lab/.virtualenvs/shoppingMall/lib/python3.6/site-packages/rest_framework/views.py", line 480, in dispatch
    response = handler(request, *args, **kwargs)
  File "/home/changle-lab/Desktop/shopping_mall/shoppingMall/meiduo_mall/meiduo_mall/apps/oauth/views.py", line 50, in get
    return Response(data)
TypeError: __init__() takes 1 positional argument but 2 were given
ERROR 2019-09-12 14:25:03,648 basehttp 124 "GET /oauth/qq/authorization/?next=/ HTTP/1.1" 500 19062
ERROR 2019-09-12 14:26:02,251 exception 135 Internal Server Error: /oauth/qq/authorization/
Traceback (most recent call last):
  File "/home/changle-lab/.virtualenvs/shoppingMall/lib/python3.6/site-packages/django/core/handlers/exception.py", line 41, in inner
    response = get_response(request)
  File "/home/changle-lab/.virtualenvs/shoppingMall/lib/python3.6/site-packages/django/core/handlers/base.py", line 187, in _get_response
    response = self.process_exception_by_middleware(e, request)
  File "/home/changle-lab/.virtualenvs/shoppingMall/lib/python3.6/site-packages/django/core/handlers/base.py", line 185, in _get_response
    response = wrapped_callback(request, *callback_args, **callback_kwargs)
  File "/home/changle-lab/.virtualenvs/shoppingMall/lib/python3.6/site-packages/django/views/decorators/csrf.py", line 58, in wrapped_view
    return view_func(*args, **kwargs)
  File "/home/changle-lab/.virtualenvs/shoppingMall/lib/python3.6/site-packages/django/views/generic/base.py", line 68, in view
    return self.dispatch(request, *args, **kwargs)
  File "/home/changle-lab/.virtualenvs/shoppingMall/lib/python3.6/site-packages/rest_framework/views.py", line 483, in dispatch
    response = self.handle_exception(exc)
  File "/home/changle-lab/.virtualenvs/shoppingMall/lib/python3.6/site-packages/rest_framework/views.py", line 443, in handle_exception
    self.raise_uncaught_exception(exc)
  File "/home/changle-lab/.virtualenvs/shoppingMall/lib/python3.6/site-packages/rest_framework/views.py", line 480, in dispatch
    response = handler(request, *args, **kwargs)
  File "/home/changle-lab/Desktop/shopping_mall/shoppingMall/meiduo_mall/meiduo_mall/apps/oauth/views.py", line 50, in get
    return Response(data)
TypeError: __init__() takes 1 positional argument but 2 were given
ERROR 2019-09-12 14:26:02,276 basehttp 124 "GET /oauth/qq/authorization/?next=/ HTTP/1.1" 500 19062
ERROR 2019-09-12 14:29:51,698 exception 135 Internal Server Error: /oauth/qq/authorization/
Traceback (most recent call last):
  File "/home/changle-lab/.virtualenvs/shoppingMall/lib/python3.6/site-packages/django/core/handlers/exception.py", line 41, in inner
    response = get_response(request)
  File "/home/changle-lab/.virtualenvs/shoppingMall/lib/python3.6/site-packages/django/core/handlers/base.py", line 187, in _get_response
    response = self.process_exception_by_middleware(e, request)
  File "/home/changle-lab/.virtualenvs/shoppingMall/lib/python3.6/site-packages/django/core/handlers/base.py", line 185, in _get_response
    response = wrapped_callback(request, *callback_args, **callback_kwargs)
  File "/home/changle-lab/.virtualenvs/shoppingMall/lib/python3.6/site-packages/django/views/decorators/csrf.py", line 58, in wrapped_view
    return view_func(*args, **kwargs)
  File "/home/changle-lab/.virtualenvs/shoppingMall/lib/python3.6/site-packages/django/views/generic/base.py", line 68, in view
    return self.dispatch(request, *args, **kwargs)
  File "/home/changle-lab/.virtualenvs/shoppingMall/lib/python3.6/site-packages/rest_framework/views.py", line 483, in dispatch
    response = self.handle_exception(exc)
  File "/home/changle-lab/.virtualenvs/shoppingMall/lib/python3.6/site-packages/rest_framework/views.py", line 443, in handle_exception
    self.raise_uncaught_exception(exc)
  File "/home/changle-lab/.virtualenvs/shoppingMall/lib/python3.6/site-packages/rest_framework/views.py", line 480, in dispatch
    response = handler(request, *args, **kwargs)
  File "/home/changle-lab/Desktop/shopping_mall/shoppingMall/meiduo_mall/meiduo_mall/apps/oauth/views.py", line 52, in get
    return Response(data)
TypeError: __init__() takes 1 positional argument but 2 were given
ERROR 2019-09-12 14:29:51,768 basehttp 124 "GET /oauth/qq/authorization/?next=/ HTTP/1.1" 500 19062
ERROR 2019-09-12 14:36:54,333 exception 135 Internal Server Error: /oauth/qq/authorization/
Traceback (most recent call last):
  File "/home/changle-lab/.virtualenvs/shoppingMall/lib/python3.6/site-packages/django/core/handlers/exception.py", line 41, in inner
    response = get_response(request)
  File "/home/changle-lab/.virtualenvs/shoppingMall/lib/python3.6/site-packages/django/core/handlers/base.py", line 187, in _get_response
    response = self.process_exception_by_middleware(e, request)
  File "/home/changle-lab/.virtualenvs/shoppingMall/lib/python3.6/site-packages/django/core/handlers/base.py", line 185, in _get_response
    response = wrapped_callback(request, *callback_args, **callback_kwargs)
  File "/home/changle-lab/.virtualenvs/shoppingMall/lib/python3.6/site-packages/django/views/decorators/csrf.py", line 58, in wrapped_view
    return view_func(*args, **kwargs)
  File "/home/changle-lab/.virtualenvs/shoppingMall/lib/python3.6/site-packages/django/views/generic/base.py", line 68, in view
    return self.dispatch(request, *args, **kwargs)
  File "/home/changle-lab/.virtualenvs/shoppingMall/lib/python3.6/site-packages/rest_framework/views.py", line 483, in dispatch
    response = self.handle_exception(exc)
  File "/home/changle-lab/.virtualenvs/shoppingMall/lib/python3.6/site-packages/rest_framework/views.py", line 443, in handle_exception
    self.raise_uncaught_exception(exc)
  File "/home/changle-lab/.virtualenvs/shoppingMall/lib/python3.6/site-packages/rest_framework/views.py", line 480, in dispatch
    response = handler(request, *args, **kwargs)
  File "/home/changle-lab/Desktop/shopping_mall/shoppingMall/meiduo_mall/meiduo_mall/apps/oauth/views.py", line 47, in get
    redirect_uri=settings.QQ_REDIRECT_URI, state=next)
TypeError: __init__() got multiple values for argument 'client_id'
ERROR 2019-09-12 14:36:54,369 basehttp 124 "GET /oauth/qq/authorization/?next=/ HTTP/1.1" 500 19107
ERROR 2019-09-12 15:17:51,793 exception 135 Internal Server Error: /oauth/qq/authorization/
Traceback (most recent call last):
  File "/home/changle-lab/.virtualenvs/shoppingMall/lib/python3.6/site-packages/django/core/handlers/exception.py", line 41, in inner
    response = get_response(request)
  File "/home/changle-lab/.virtualenvs/shoppingMall/lib/python3.6/site-packages/django/core/handlers/base.py", line 187, in _get_response
    response = self.process_exception_by_middleware(e, request)
  File "/home/changle-lab/.virtualenvs/shoppingMall/lib/python3.6/site-packages/django/core/handlers/base.py", line 185, in _get_response
    response = wrapped_callback(request, *callback_args, **callback_kwargs)
  File "/home/changle-lab/.virtualenvs/shoppingMall/lib/python3.6/site-packages/django/views/decorators/csrf.py", line 58, in wrapped_view
    return view_func(*args, **kwargs)
  File "/home/changle-lab/.virtualenvs/shoppingMall/lib/python3.6/site-packages/django/views/generic/base.py", line 68, in view
    return self.dispatch(request, *args, **kwargs)
  File "/home/changle-lab/.virtualenvs/shoppingMall/lib/python3.6/site-packages/rest_framework/views.py", line 483, in dispatch
    response = self.handle_exception(exc)
  File "/home/changle-lab/.virtualenvs/shoppingMall/lib/python3.6/site-packages/rest_framework/views.py", line 443, in handle_exception
    self.raise_uncaught_exception(exc)
  File "/home/changle-lab/.virtualenvs/shoppingMall/lib/python3.6/site-packages/rest_framework/views.py", line 480, in dispatch
    response = handler(request, *args, **kwargs)
  File "/home/changle-lab/Desktop/shopping_mall/shoppingMall/meiduo_mall/meiduo_mall/apps/oauth/views.py", line 52, in get
    state=next)
TypeError: __init__() got multiple values for argument 'client_id'
ERROR 2019-09-12 15:17:51,845 basehttp 124 "GET /oauth/qq/authorization/?next=/ HTTP/1.1" 500 19068
ERROR 2019-09-12 15:20:08,321 exception 135 Internal Server Error: /oauth/qq/authorization/
Traceback (most recent call last):
  File "/home/changle-lab/.virtualenvs/shoppingMall/lib/python3.6/site-packages/django/core/handlers/exception.py", line 41, in inner
    response = get_response(request)
  File "/home/changle-lab/.virtualenvs/shoppingMall/lib/python3.6/site-packages/django/core/handlers/base.py", line 187, in _get_response
    response = self.process_exception_by_middleware(e, request)
  File "/home/changle-lab/.virtualenvs/shoppingMall/lib/python3.6/site-packages/django/core/handlers/base.py", line 185, in _get_response
    response = wrapped_callback(request, *callback_args, **callback_kwargs)
  File "/home/changle-lab/.virtualenvs/shoppingMall/lib/python3.6/site-packages/django/views/decorators/csrf.py", line 58, in wrapped_view
    return view_func(*args, **kwargs)
  File "/home/changle-lab/.virtualenvs/shoppingMall/lib/python3.6/site-packages/django/views/generic/base.py", line 68, in view
    return self.dispatch(request, *args, **kwargs)
  File "/home/changle-lab/.virtualenvs/shoppingMall/lib/python3.6/site-packages/rest_framework/views.py", line 483, in dispatch
    response = self.handle_exception(exc)
  File "/home/changle-lab/.virtualenvs/shoppingMall/lib/python3.6/site-packages/rest_framework/views.py", line 443, in handle_exception
    self.raise_uncaught_exception(exc)
  File "/home/changle-lab/.virtualenvs/shoppingMall/lib/python3.6/site-packages/rest_framework/views.py", line 480, in dispatch
    response = handler(request, *args, **kwargs)
  File "/home/changle-lab/Desktop/shopping_mall/shoppingMall/meiduo_mall/meiduo_mall/apps/oauth/views.py", line 52, in get
    state='/')
TypeError: __init__() got multiple values for argument 'client_id'
ERROR 2019-09-12 15:20:08,352 basehttp 124 "GET /oauth/qq/authorization/?next=/ HTTP/1.1" 500 19067
ERROR 2019-09-12 15:21:19,292 exception 135 Internal Server Error: /oauth/qq/authorization/
Traceback (most recent call last):
  File "/home/changle-lab/.virtualenvs/shoppingMall/lib/python3.6/site-packages/django/core/handlers/exception.py", line 41, in inner
    response = get_response(request)
  File "/home/changle-lab/.virtualenvs/shoppingMall/lib/python3.6/site-packages/django/core/handlers/base.py", line 187, in _get_response
    response = self.process_exception_by_middleware(e, request)
  File "/home/changle-lab/.virtualenvs/shoppingMall/lib/python3.6/site-packages/django/core/handlers/base.py", line 185, in _get_response
    response = wrapped_callback(request, *callback_args, **callback_kwargs)
  File "/home/changle-lab/.virtualenvs/shoppingMall/lib/python3.6/site-packages/django/views/decorators/csrf.py", line 58, in wrapped_view
    return view_func(*args, **kwargs)
  File "/home/changle-lab/.virtualenvs/shoppingMall/lib/python3.6/site-packages/django/views/generic/base.py", line 68, in view
    return self.dispatch(request, *args, **kwargs)
  File "/home/changle-lab/.virtualenvs/shoppingMall/lib/python3.6/site-packages/rest_framework/views.py", line 483, in dispatch
    response = self.handle_exception(exc)
  File "/home/changle-lab/.virtualenvs/shoppingMall/lib/python3.6/site-packages/rest_framework/views.py", line 443, in handle_exception
    self.raise_uncaught_exception(exc)
  File "/home/changle-lab/.virtualenvs/shoppingMall/lib/python3.6/site-packages/rest_framework/views.py", line 480, in dispatch
    response = handler(request, *args, **kwargs)
  File "/home/changle-lab/Desktop/shopping_mall/shoppingMall/meiduo_mall/meiduo_mall/apps/oauth/views.py", line 57, in get
    return Response(data)
TypeError: __init__() takes 1 positional argument but 2 were given
ERROR 2019-09-12 15:21:19,329 basehttp 124 "GET /oauth/qq/authorization/?next=/ HTTP/1.1" 500 19062
ERROR 2019-09-12 17:11:47,769 exception 135 Internal Server Error: /oauth/qq/authorization/
Traceback (most recent call last):
  File "/home/changle-lab/.virtualenvs/shoppingMall/lib/python3.6/site-packages/django/core/handlers/exception.py", line 41, in inner
    response = get_response(request)
  File "/home/changle-lab/.virtualenvs/shoppingMall/lib/python3.6/site-packages/django/core/handlers/base.py", line 187, in _get_response
    response = self.process_exception_by_middleware(e, request)
  File "/home/changle-lab/.virtualenvs/shoppingMall/lib/python3.6/site-packages/django/core/handlers/base.py", line 185, in _get_response
    response = wrapped_callback(request, *callback_args, **callback_kwargs)
  File "/home/changle-lab/.virtualenvs/shoppingMall/lib/python3.6/site-packages/django/views/decorators/csrf.py", line 58, in wrapped_view
    return view_func(*args, **kwargs)
  File "/home/changle-lab/.virtualenvs/shoppingMall/lib/python3.6/site-packages/django/views/generic/base.py", line 68, in view
    return self.dispatch(request, *args, **kwargs)
  File "/home/changle-lab/.virtualenvs/shoppingMall/lib/python3.6/site-packages/rest_framework/views.py", line 483, in dispatch
    response = self.handle_exception(exc)
  File "/home/changle-lab/.virtualenvs/shoppingMall/lib/python3.6/site-packages/rest_framework/views.py", line 443, in handle_exception
    self.raise_uncaught_exception(exc)
  File "/home/changle-lab/.virtualenvs/shoppingMall/lib/python3.6/site-packages/rest_framework/views.py", line 480, in dispatch
    response = handler(request, *args, **kwargs)
  File "/home/changle-lab/Desktop/shopping_mall/shoppingMall/meiduo_mall/meiduo_mall/apps/oauth/views.py", line 57, in get
    return Response(data)
TypeError: __init__() takes 1 positional argument but 2 were given
ERROR 2019-09-12 17:11:47,809 basehttp 124 "GET /oauth/qq/authorization/?next=/ HTTP/1.1" 500 19062
ERROR 2019-09-12 17:12:09,485 exception 135 Internal Server Error: /oauth/qq/authorization/
Traceback (most recent call last):
  File "/home/changle-lab/.virtualenvs/shoppingMall/lib/python3.6/site-packages/django/core/handlers/exception.py", line 41, in inner
    response = get_response(request)
  File "/home/changle-lab/.virtualenvs/shoppingMall/lib/python3.6/site-packages/django/core/handlers/base.py", line 187, in _get_response
    response = self.process_exception_by_middleware(e, request)
  File "/home/changle-lab/.virtualenvs/shoppingMall/lib/python3.6/site-packages/django/core/handlers/base.py", line 185, in _get_response
    response = wrapped_callback(request, *callback_args, **callback_kwargs)
  File "/home/changle-lab/.virtualenvs/shoppingMall/lib/python3.6/site-packages/django/views/decorators/csrf.py", line 58, in wrapped_view
    return view_func(*args, **kwargs)
  File "/home/changle-lab/.virtualenvs/shoppingMall/lib/python3.6/site-packages/django/views/generic/base.py", line 68, in view
    return self.dispatch(request, *args, **kwargs)
  File "/home/changle-lab/.virtualenvs/shoppingMall/lib/python3.6/site-packages/rest_framework/views.py", line 483, in dispatch
    response = self.handle_exception(exc)
  File "/home/changle-lab/.virtualenvs/shoppingMall/lib/python3.6/site-packages/rest_framework/views.py", line 443, in handle_exception
    self.raise_uncaught_exception(exc)
  File "/home/changle-lab/.virtualenvs/shoppingMall/lib/python3.6/site-packages/rest_framework/views.py", line 480, in dispatch
    response = handler(request, *args, **kwargs)
  File "/home/changle-lab/Desktop/shopping_mall/shoppingMall/meiduo_mall/meiduo_mall/apps/oauth/views.py", line 57, in get
    return Response(data)
TypeError: __init__() takes 1 positional argument but 2 were given
ERROR 2019-09-12 17:12:09,511 basehttp 124 "GET /oauth/qq/authorization/?next=/ HTTP/1.1" 500 19062
ERROR 2019-09-12 17:12:17,358 exception 135 Internal Server Error: /oauth/qq/authorization/
Traceback (most recent call last):
  File "/home/changle-lab/.virtualenvs/shoppingMall/lib/python3.6/site-packages/django/core/handlers/exception.py", line 41, in inner
    response = get_response(request)
  File "/home/changle-lab/.virtualenvs/shoppingMall/lib/python3.6/site-packages/django/core/handlers/base.py", line 187, in _get_response
    response = self.process_exception_by_middleware(e, request)
  File "/home/changle-lab/.virtualenvs/shoppingMall/lib/python3.6/site-packages/django/core/handlers/base.py", line 185, in _get_response
    response = wrapped_callback(request, *callback_args, **callback_kwargs)
  File "/home/changle-lab/.virtualenvs/shoppingMall/lib/python3.6/site-packages/django/views/decorators/csrf.py", line 58, in wrapped_view
    return view_func(*args, **kwargs)
  File "/home/changle-lab/.virtualenvs/shoppingMall/lib/python3.6/site-packages/django/views/generic/base.py", line 68, in view
    return self.dispatch(request, *args, **kwargs)
  File "/home/changle-lab/.virtualenvs/shoppingMall/lib/python3.6/site-packages/rest_framework/views.py", line 483, in dispatch
    response = self.handle_exception(exc)
  File "/home/changle-lab/.virtualenvs/shoppingMall/lib/python3.6/site-packages/rest_framework/views.py", line 443, in handle_exception
    self.raise_uncaught_exception(exc)
  File "/home/changle-lab/.virtualenvs/shoppingMall/lib/python3.6/site-packages/rest_framework/views.py", line 480, in dispatch
    response = handler(request, *args, **kwargs)
  File "/home/changle-lab/Desktop/shopping_mall/shoppingMall/meiduo_mall/meiduo_mall/apps/oauth/views.py", line 57, in get
    return Response(data)
TypeError: __init__() takes 1 positional argument but 2 were given
ERROR 2019-09-12 17:12:17,387 basehttp 124 "GET /oauth/qq/authorization/?next=/ HTTP/1.1" 500 19062
ERROR 2019-09-12 17:12:18,729 exception 135 Internal Server Error: /oauth/qq/authorization/
Traceback (most recent call last):
  File "/home/changle-lab/.virtualenvs/shoppingMall/lib/python3.6/site-packages/django/core/handlers/exception.py", line 41, in inner
    response = get_response(request)
  File "/home/changle-lab/.virtualenvs/shoppingMall/lib/python3.6/site-packages/django/core/handlers/base.py", line 187, in _get_response
    response = self.process_exception_by_middleware(e, request)
  File "/home/changle-lab/.virtualenvs/shoppingMall/lib/python3.6/site-packages/django/core/handlers/base.py", line 185, in _get_response
    response = wrapped_callback(request, *callback_args, **callback_kwargs)
  File "/home/changle-lab/.virtualenvs/shoppingMall/lib/python3.6/site-packages/django/views/decorators/csrf.py", line 58, in wrapped_view
    return view_func(*args, **kwargs)
  File "/home/changle-lab/.virtualenvs/shoppingMall/lib/python3.6/site-packages/django/views/generic/base.py", line 68, in view
    return self.dispatch(request, *args, **kwargs)
  File "/home/changle-lab/.virtualenvs/shoppingMall/lib/python3.6/site-packages/rest_framework/views.py", line 483, in dispatch
    response = self.handle_exception(exc)
  File "/home/changle-lab/.virtualenvs/shoppingMall/lib/python3.6/site-packages/rest_framework/views.py", line 443, in handle_exception
    self.raise_uncaught_exception(exc)
  File "/home/changle-lab/.virtualenvs/shoppingMall/lib/python3.6/site-packages/rest_framework/views.py", line 480, in dispatch
    response = handler(request, *args, **kwargs)
  File "/home/changle-lab/Desktop/shopping_mall/shoppingMall/meiduo_mall/meiduo_mall/apps/oauth/views.py", line 57, in get
    return Response(data)
TypeError: __init__() takes 1 positional argument but 2 were given
ERROR 2019-09-12 17:12:18,762 basehttp 124 "GET /oauth/qq/authorization/?next=/ HTTP/1.1" 500 19062
ERROR 2019-09-12 17:12:28,202 exception 135 Internal Server Error: /oauth/qq/authorization/
Traceback (most recent call last):
  File "/home/changle-lab/.virtualenvs/shoppingMall/lib/python3.6/site-packages/django/core/handlers/exception.py", line 41, in inner
    response = get_response(request)
  File "/home/changle-lab/.virtualenvs/shoppingMall/lib/python3.6/site-packages/django/core/handlers/base.py", line 187, in _get_response
    response = self.process_exception_by_middleware(e, request)
  File "/home/changle-lab/.virtualenvs/shoppingMall/lib/python3.6/site-packages/django/core/handlers/base.py", line 185, in _get_response
    response = wrapped_callback(request, *callback_args, **callback_kwargs)
  File "/home/changle-lab/.virtualenvs/shoppingMall/lib/python3.6/site-packages/django/views/decorators/csrf.py", line 58, in wrapped_view
    return view_func(*args, **kwargs)
  File "/home/changle-lab/.virtualenvs/shoppingMall/lib/python3.6/site-packages/django/views/generic/base.py", line 68, in view
    return self.dispatch(request, *args, **kwargs)
  File "/home/changle-lab/.virtualenvs/shoppingMall/lib/python3.6/site-packages/rest_framework/views.py", line 483, in dispatch
    response = self.handle_exception(exc)
  File "/home/changle-lab/.virtualenvs/shoppingMall/lib/python3.6/site-packages/rest_framework/views.py", line 443, in handle_exception
    self.raise_uncaught_exception(exc)
  File "/home/changle-lab/.virtualenvs/shoppingMall/lib/python3.6/site-packages/rest_framework/views.py", line 480, in dispatch
    response = handler(request, *args, **kwargs)
  File "/home/changle-lab/Desktop/shopping_mall/shoppingMall/meiduo_mall/meiduo_mall/apps/oauth/views.py", line 57, in get
    return Response(data)
TypeError: __init__() takes 1 positional argument but 2 were given
ERROR 2019-09-12 17:12:28,232 basehttp 124 "GET /oauth/qq/authorization/?next=/ HTTP/1.1" 500 19062
ERROR 2019-09-12 17:23:22,779 exception 135 Internal Server Error: /oauth/qq/authorization/
Traceback (most recent call last):
  File "/home/changle-lab/.virtualenvs/shoppingMall/lib/python3.6/site-packages/django/core/handlers/exception.py", line 41, in inner
    response = get_response(request)
  File "/home/changle-lab/.virtualenvs/shoppingMall/lib/python3.6/site-packages/django/core/handlers/base.py", line 187, in _get_response
    response = self.process_exception_by_middleware(e, request)
  File "/home/changle-lab/.virtualenvs/shoppingMall/lib/python3.6/site-packages/django/core/handlers/base.py", line 185, in _get_response
    response = wrapped_callback(request, *callback_args, **callback_kwargs)
  File "/home/changle-lab/.virtualenvs/shoppingMall/lib/python3.6/site-packages/django/views/decorators/csrf.py", line 58, in wrapped_view
    return view_func(*args, **kwargs)
  File "/home/changle-lab/.virtualenvs/shoppingMall/lib/python3.6/site-packages/django/views/generic/base.py", line 68, in view
    return self.dispatch(request, *args, **kwargs)
  File "/home/changle-lab/.virtualenvs/shoppingMall/lib/python3.6/site-packages/rest_framework/views.py", line 483, in dispatch
    response = self.handle_exception(exc)
  File "/home/changle-lab/.virtualenvs/shoppingMall/lib/python3.6/site-packages/rest_framework/views.py", line 443, in handle_exception
    self.raise_uncaught_exception(exc)
  File "/home/changle-lab/.virtualenvs/shoppingMall/lib/python3.6/site-packages/rest_framework/views.py", line 480, in dispatch
    response = handler(request, *args, **kwargs)
  File "/home/changle-lab/Desktop/shopping_mall/shoppingMall/meiduo_mall/meiduo_mall/apps/oauth/views.py", line 57, in get
    return Response(data)
TypeError: __init__() takes 1 positional argument but 2 were given
ERROR 2019-09-12 17:23:22,808 basehttp 124 "GET /oauth/qq/authorization/?next=/ HTTP/1.1" 500 19063
ERROR 2019-09-12 17:26:59,894 exception 135 Internal Server Error: /oauth/qq/authorization/
Traceback (most recent call last):
  File "/home/changle-lab/.virtualenvs/shoppingMall/lib/python3.6/site-packages/django/core/handlers/exception.py", line 41, in inner
    response = get_response(request)
  File "/home/changle-lab/.virtualenvs/shoppingMall/lib/python3.6/site-packages/django/core/handlers/base.py", line 187, in _get_response
    response = self.process_exception_by_middleware(e, request)
  File "/home/changle-lab/.virtualenvs/shoppingMall/lib/python3.6/site-packages/django/core/handlers/base.py", line 185, in _get_response
    response = wrapped_callback(request, *callback_args, **callback_kwargs)
  File "/home/changle-lab/.virtualenvs/shoppingMall/lib/python3.6/site-packages/django/views/decorators/csrf.py", line 58, in wrapped_view
    return view_func(*args, **kwargs)
  File "/home/changle-lab/.virtualenvs/shoppingMall/lib/python3.6/site-packages/django/views/generic/base.py", line 68, in view
    return self.dispatch(request, *args, **kwargs)
  File "/home/changle-lab/.virtualenvs/shoppingMall/lib/python3.6/site-packages/rest_framework/views.py", line 483, in dispatch
    response = self.handle_exception(exc)
  File "/home/changle-lab/.virtualenvs/shoppingMall/lib/python3.6/site-packages/rest_framework/views.py", line 443, in handle_exception
    self.raise_uncaught_exception(exc)
  File "/home/changle-lab/.virtualenvs/shoppingMall/lib/python3.6/site-packages/rest_framework/views.py", line 480, in dispatch
    response = handler(request, *args, **kwargs)
  File "/home/changle-lab/Desktop/shopping_mall/shoppingMall/meiduo_mall/meiduo_mall/apps/oauth/views.py", line 52, in get
    state='/')
TypeError: __init__() got multiple values for argument 'client_id'
ERROR 2019-09-12 17:26:59,918 basehttp 124 "GET /oauth/qq/authorization/?next=/ HTTP/1.1" 500 19068
ERROR 2019-09-12 17:32:05,369 exception 135 Internal Server Error: /oauth/qq/authorization/
Traceback (most recent call last):
  File "/home/changle-lab/.virtualenvs/shoppingMall/lib/python3.6/site-packages/django/core/handlers/exception.py", line 41, in inner
    response = get_response(request)
  File "/home/changle-lab/.virtualenvs/shoppingMall/lib/python3.6/site-packages/django/core/handlers/base.py", line 187, in _get_response
    response = self.process_exception_by_middleware(e, request)
  File "/home/changle-lab/.virtualenvs/shoppingMall/lib/python3.6/site-packages/django/core/handlers/base.py", line 185, in _get_response
    response = wrapped_callback(request, *callback_args, **callback_kwargs)
  File "/home/changle-lab/.virtualenvs/shoppingMall/lib/python3.6/site-packages/django/views/decorators/csrf.py", line 58, in wrapped_view
    return view_func(*args, **kwargs)
  File "/home/changle-lab/.virtualenvs/shoppingMall/lib/python3.6/site-packages/django/views/generic/base.py", line 68, in view
    return self.dispatch(request, *args, **kwargs)
  File "/home/changle-lab/.virtualenvs/shoppingMall/lib/python3.6/site-packages/rest_framework/views.py", line 483, in dispatch
    response = self.handle_exception(exc)
  File "/home/changle-lab/.virtualenvs/shoppingMall/lib/python3.6/site-packages/rest_framework/views.py", line 443, in handle_exception
    self.raise_uncaught_exception(exc)
  File "/home/changle-lab/.virtualenvs/shoppingMall/lib/python3.6/site-packages/rest_framework/views.py", line 480, in dispatch
    response = handler(request, *args, **kwargs)
  File "/home/changle-lab/Desktop/shopping_mall/shoppingMall/meiduo_mall/meiduo_mall/apps/oauth/views.py", line 54, in get
    state='/')
TypeError: __init__() got an unexpected keyword argument 'response_type'
ERROR 2019-09-12 17:32:05,395 basehttp 124 "GET /oauth/qq/authorization/?next=/ HTTP/1.1" 500 19080
INFO 2019-09-12 18:28:01,053 basehttp 124 "GET /usernames/changyu/count/ HTTP/1.1" 200 11
ERROR 2019-09-12 18:37:03,872 exception 135 Internal Server Error: /oauth/qq/authorization/
Traceback (most recent call last):
  File "/home/changle-lab/.virtualenvs/shoppingMall/lib/python3.6/site-packages/django/core/handlers/exception.py", line 41, in inner
    response = get_response(request)
  File "/home/changle-lab/.virtualenvs/shoppingMall/lib/python3.6/site-packages/django/core/handlers/base.py", line 187, in _get_response
    response = self.process_exception_by_middleware(e, request)
  File "/home/changle-lab/.virtualenvs/shoppingMall/lib/python3.6/site-packages/django/core/handlers/base.py", line 185, in _get_response
    response = wrapped_callback(request, *callback_args, **callback_kwargs)
  File "/home/changle-lab/.virtualenvs/shoppingMall/lib/python3.6/site-packages/django/views/decorators/csrf.py", line 58, in wrapped_view
    return view_func(*args, **kwargs)
  File "/home/changle-lab/.virtualenvs/shoppingMall/lib/python3.6/site-packages/django/views/generic/base.py", line 68, in view
    return self.dispatch(request, *args, **kwargs)
  File "/home/changle-lab/.virtualenvs/shoppingMall/lib/python3.6/site-packages/rest_framework/views.py", line 483, in dispatch
    response = self.handle_exception(exc)
  File "/home/changle-lab/.virtualenvs/shoppingMall/lib/python3.6/site-packages/rest_framework/views.py", line 443, in handle_exception
    self.raise_uncaught_exception(exc)
  File "/home/changle-lab/.virtualenvs/shoppingMall/lib/python3.6/site-packages/rest_framework/views.py", line 480, in dispatch
    response = handler(request, *args, **kwargs)
  File "/home/changle-lab/Desktop/shopping_mall/shoppingMall/meiduo_mall/meiduo_mall/apps/oauth/views.py", line 54, in get
    state='/')
TypeError: __init__() got multiple values for argument 'client_id'
ERROR 2019-09-12 18:37:03,919 basehttp 124 "GET /oauth/qq/authorization/?next=/ HTTP/1.1" 500 19011
ERROR 2019-09-12 18:37:27,725 exception 135 Internal Server Error: /oauth/qq/authorization/
Traceback (most recent call last):
  File "/home/changle-lab/.virtualenvs/shoppingMall/lib/python3.6/site-packages/django/core/handlers/exception.py", line 41, in inner
    response = get_response(request)
  File "/home/changle-lab/.virtualenvs/shoppingMall/lib/python3.6/site-packages/django/core/handlers/base.py", line 187, in _get_response
    response = self.process_exception_by_middleware(e, request)
  File "/home/changle-lab/.virtualenvs/shoppingMall/lib/python3.6/site-packages/django/core/handlers/base.py", line 185, in _get_response
    response = wrapped_callback(request, *callback_args, **callback_kwargs)
  File "/home/changle-lab/.virtualenvs/shoppingMall/lib/python3.6/site-packages/django/views/decorators/csrf.py", line 58, in wrapped_view
    return view_func(*args, **kwargs)
  File "/home/changle-lab/.virtualenvs/shoppingMall/lib/python3.6/site-packages/django/views/generic/base.py", line 68, in view
    return self.dispatch(request, *args, **kwargs)
  File "/home/changle-lab/.virtualenvs/shoppingMall/lib/python3.6/site-packages/rest_framework/views.py", line 483, in dispatch
    response = self.handle_exception(exc)
  File "/home/changle-lab/.virtualenvs/shoppingMall/lib/python3.6/site-packages/rest_framework/views.py", line 443, in handle_exception
    self.raise_uncaught_exception(exc)
  File "/home/changle-lab/.virtualenvs/shoppingMall/lib/python3.6/site-packages/rest_framework/views.py", line 480, in dispatch
    response = handler(request, *args, **kwargs)
  File "/home/changle-lab/Desktop/shopping_mall/shoppingMall/meiduo_mall/meiduo_mall/apps/oauth/views.py", line 59, in get
    return Response(data)
TypeError: __init__() takes 1 positional argument but 2 were given
ERROR 2019-09-12 18:37:27,765 basehttp 124 "GET /oauth/qq/authorization/?next=/ HTTP/1.1" 500 19006
WARNING 2019-09-12 18:45:46,803 basehttp 124 "GET /oauth/qq/authorization/?next=/ HTTP/1.1" 405 45
WARNING 2019-09-12 18:47:14,841 basehttp 124 "GET /oauth/qq/authorization/?next=/ HTTP/1.1" 405 45
ERROR 2019-09-12 18:47:49,328 exception 135 Internal Server Error: /oauth/qq/authorization/
Traceback (most recent call last):
  File "/home/changle-lab/.virtualenvs/shoppingMall/lib/python3.6/site-packages/django/core/handlers/exception.py", line 41, in inner
    response = get_response(request)
  File "/home/changle-lab/.virtualenvs/shoppingMall/lib/python3.6/site-packages/django/core/handlers/base.py", line 187, in _get_response
    response = self.process_exception_by_middleware(e, request)
  File "/home/changle-lab/.virtualenvs/shoppingMall/lib/python3.6/site-packages/django/core/handlers/base.py", line 185, in _get_response
    response = wrapped_callback(request, *callback_args, **callback_kwargs)
  File "/home/changle-lab/.virtualenvs/shoppingMall/lib/python3.6/site-packages/django/views/decorators/csrf.py", line 58, in wrapped_view
    return view_func(*args, **kwargs)
  File "/home/changle-lab/.virtualenvs/shoppingMall/lib/python3.6/site-packages/django/views/generic/base.py", line 68, in view
    return self.dispatch(request, *args, **kwargs)
  File "/home/changle-lab/.virtualenvs/shoppingMall/lib/python3.6/site-packages/rest_framework/views.py", line 483, in dispatch
    response = self.handle_exception(exc)
  File "/home/changle-lab/.virtualenvs/shoppingMall/lib/python3.6/site-packages/rest_framework/views.py", line 443, in handle_exception
    self.raise_uncaught_exception(exc)
  File "/home/changle-lab/.virtualenvs/shoppingMall/lib/python3.6/site-packages/rest_framework/views.py", line 480, in dispatch
    response = handler(request, *args, **kwargs)
TypeError: get() takes 1 positional argument but 2 were given
ERROR 2019-09-12 18:47:49,352 basehttp 124 "GET /oauth/qq/authorization/?next=/ HTTP/1.1" 500 18848
ERROR 2019-09-12 18:48:38,425 exception 135 Internal Server Error: /oauth/qq/authorization/
Traceback (most recent call last):
  File "/home/changle-lab/.virtualenvs/shoppingMall/lib/python3.6/site-packages/django/core/handlers/exception.py", line 41, in inner
    response = get_response(request)
  File "/home/changle-lab/.virtualenvs/shoppingMall/lib/python3.6/site-packages/django/core/handlers/base.py", line 187, in _get_response
    response = self.process_exception_by_middleware(e, request)
  File "/home/changle-lab/.virtualenvs/shoppingMall/lib/python3.6/site-packages/django/core/handlers/base.py", line 185, in _get_response
    response = wrapped_callback(request, *callback_args, **callback_kwargs)
  File "/home/changle-lab/.virtualenvs/shoppingMall/lib/python3.6/site-packages/django/views/decorators/csrf.py", line 58, in wrapped_view
    return view_func(*args, **kwargs)
  File "/home/changle-lab/.virtualenvs/shoppingMall/lib/python3.6/site-packages/django/views/generic/base.py", line 68, in view
    return self.dispatch(request, *args, **kwargs)
  File "/home/changle-lab/.virtualenvs/shoppingMall/lib/python3.6/site-packages/rest_framework/views.py", line 485, in dispatch
    self.response = self.finalize_response(request, response, *args, **kwargs)
  File "/home/changle-lab/.virtualenvs/shoppingMall/lib/python3.6/site-packages/rest_framework/views.py", line 400, in finalize_response
    % type(response)
AssertionError: Expected a `Response`, `HttpResponse` or `HttpStreamingResponse` to be returned from the view, but received a `<class 'str'>`
ERROR 2019-09-12 18:48:38,468 basehttp 124 "GET /oauth/qq/authorization/?next=/ HTTP/1.1" 500 89834
WARNING 2019-09-12 18:50:16,799 base 152 Not Found: /oauth/qq/authorization/
WARNING 2019-09-12 18:50:16,800 basehttp 124 "GET /oauth/qq/authorization/?next=/ HTTP/1.1" 404 3090
WARNING 2019-09-12 18:50:28,825 base 152 Not Found: /oauth/qq/authorization/
WARNING 2019-09-12 18:50:28,826 basehttp 124 "GET /oauth/qq/authorization/?next=/ HTTP/1.1" 404 3090
ERROR 2019-09-12 18:51:32,643 exception 135 Internal Server Error: /oauth/qq/authorization/
Traceback (most recent call last):
  File "/home/changle-lab/.virtualenvs/shoppingMall/lib/python3.6/site-packages/django/core/handlers/exception.py", line 41, in inner
    response = get_response(request)
  File "/home/changle-lab/.virtualenvs/shoppingMall/lib/python3.6/site-packages/django/core/handlers/base.py", line 187, in _get_response
    response = self.process_exception_by_middleware(e, request)
  File "/home/changle-lab/.virtualenvs/shoppingMall/lib/python3.6/site-packages/django/core/handlers/base.py", line 185, in _get_response
    response = wrapped_callback(request, *callback_args, **callback_kwargs)
  File "/home/changle-lab/.virtualenvs/shoppingMall/lib/python3.6/site-packages/django/views/decorators/csrf.py", line 58, in wrapped_view
    return view_func(*args, **kwargs)
  File "/home/changle-lab/.virtualenvs/shoppingMall/lib/python3.6/site-packages/django/views/generic/base.py", line 68, in view
    return self.dispatch(request, *args, **kwargs)
  File "/home/changle-lab/.virtualenvs/shoppingMall/lib/python3.6/site-packages/rest_framework/views.py", line 483, in dispatch
    response = self.handle_exception(exc)
  File "/home/changle-lab/.virtualenvs/shoppingMall/lib/python3.6/site-packages/rest_framework/views.py", line 443, in handle_exception
    self.raise_uncaught_exception(exc)
  File "/home/changle-lab/.virtualenvs/shoppingMall/lib/python3.6/site-packages/rest_framework/views.py", line 480, in dispatch
    response = handler(request, *args, **kwargs)
  File "/home/changle-lab/Desktop/shopping_mall/shoppingMall/meiduo_mall/meiduo_mall/apps/oauth/views.py", line 95, in get
    return Response(data)
TypeError: __init__() takes 1 positional argument but 2 were given
ERROR 2019-09-12 18:51:32,667 basehttp 124 "GET /oauth/qq/authorization/?next=/ HTTP/1.1" 500 19006
ERROR 2019-09-12 18:59:07,594 exception 135 Internal Server Error: /oauth/qq/authorization/
Traceback (most recent call last):
  File "/home/changle-lab/.virtualenvs/shoppingMall/lib/python3.6/site-packages/django/core/handlers/exception.py", line 41, in inner
    response = get_response(request)
  File "/home/changle-lab/.virtualenvs/shoppingMall/lib/python3.6/site-packages/django/core/handlers/base.py", line 187, in _get_response
    response = self.process_exception_by_middleware(e, request)
  File "/home/changle-lab/.virtualenvs/shoppingMall/lib/python3.6/site-packages/django/core/handlers/base.py", line 185, in _get_response
    response = wrapped_callback(request, *callback_args, **callback_kwargs)
  File "/home/changle-lab/.virtualenvs/shoppingMall/lib/python3.6/site-packages/django/views/decorators/csrf.py", line 58, in wrapped_view
    return view_func(*args, **kwargs)
  File "/home/changle-lab/.virtualenvs/shoppingMall/lib/python3.6/site-packages/django/views/generic/base.py", line 68, in view
    return self.dispatch(request, *args, **kwargs)
  File "/home/changle-lab/.virtualenvs/shoppingMall/lib/python3.6/site-packages/rest_framework/views.py", line 483, in dispatch
    response = self.handle_exception(exc)
  File "/home/changle-lab/.virtualenvs/shoppingMall/lib/python3.6/site-packages/rest_framework/views.py", line 443, in handle_exception
    self.raise_uncaught_exception(exc)
  File "/home/changle-lab/.virtualenvs/shoppingMall/lib/python3.6/site-packages/rest_framework/views.py", line 480, in dispatch
    response = handler(request, *args, **kwargs)
  File "/home/changle-lab/Desktop/shopping_mall/shoppingMall/meiduo_mall/meiduo_mall/apps/oauth/views.py", line 70, in get
    login_url = oauth.get_login_url()
AttributeError: 'OAuthQQ' object has no attribute 'get_login_url'
ERROR 2019-09-12 18:59:07,620 basehttp 124 "GET /oauth/qq/authorization/?next=/ HTTP/1.1" 500 19016
ERROR 2019-09-12 19:04:15,938 exception 135 Internal Server Error: /oauth/qq/authorization/
Traceback (most recent call last):
  File "/home/changle-lab/.virtualenvs/shoppingMall/lib/python3.6/site-packages/django/core/handlers/exception.py", line 41, in inner
    response = get_response(request)
  File "/home/changle-lab/.virtualenvs/shoppingMall/lib/python3.6/site-packages/django/core/handlers/base.py", line 187, in _get_response
    response = self.process_exception_by_middleware(e, request)
  File "/home/changle-lab/.virtualenvs/shoppingMall/lib/python3.6/site-packages/django/core/handlers/base.py", line 185, in _get_response
    response = wrapped_callback(request, *callback_args, **callback_kwargs)
  File "/home/changle-lab/.virtualenvs/shoppingMall/lib/python3.6/site-packages/django/views/decorators/csrf.py", line 58, in wrapped_view
    return view_func(*args, **kwargs)
  File "/home/changle-lab/.virtualenvs/shoppingMall/lib/python3.6/site-packages/django/views/generic/base.py", line 68, in view
    return self.dispatch(request, *args, **kwargs)
  File "/home/changle-lab/.virtualenvs/shoppingMall/lib/python3.6/site-packages/rest_framework/views.py", line 483, in dispatch
    response = self.handle_exception(exc)
  File "/home/changle-lab/.virtualenvs/shoppingMall/lib/python3.6/site-packages/rest_framework/views.py", line 443, in handle_exception
    self.raise_uncaught_exception(exc)
  File "/home/changle-lab/.virtualenvs/shoppingMall/lib/python3.6/site-packages/rest_framework/views.py", line 480, in dispatch
    response = handler(request, *args, **kwargs)
  File "/home/changle-lab/Desktop/shopping_mall/shoppingMall/meiduo_mall/meiduo_mall/apps/oauth/views.py", line 72, in get
    return Response({'login_url': login_url})
TypeError: __init__() takes 1 positional argument but 2 were given
ERROR 2019-09-12 19:04:15,967 basehttp 124 "GET /oauth/qq/authorization/?next=/ HTTP/1.1" 500 19026
ERROR 2019-09-12 19:21:30,152 exception 135 Internal Server Error: /oauth/qq/authorization/
Traceback (most recent call last):
  File "/home/changle-lab/.virtualenvs/shoppingMall/lib/python3.6/site-packages/django/core/handlers/exception.py", line 41, in inner
    response = get_response(request)
  File "/home/changle-lab/.virtualenvs/shoppingMall/lib/python3.6/site-packages/django/core/handlers/base.py", line 187, in _get_response
    response = self.process_exception_by_middleware(e, request)
  File "/home/changle-lab/.virtualenvs/shoppingMall/lib/python3.6/site-packages/django/core/handlers/base.py", line 185, in _get_response
    response = wrapped_callback(request, *callback_args, **callback_kwargs)
  File "/home/changle-lab/.virtualenvs/shoppingMall/lib/python3.6/site-packages/django/views/decorators/csrf.py", line 58, in wrapped_view
    return view_func(*args, **kwargs)
  File "/home/changle-lab/.virtualenvs/shoppingMall/lib/python3.6/site-packages/django/views/generic/base.py", line 68, in view
    return self.dispatch(request, *args, **kwargs)
  File "/home/changle-lab/.virtualenvs/shoppingMall/lib/python3.6/site-packages/rest_framework/views.py", line 483, in dispatch
    response = self.handle_exception(exc)
  File "/home/changle-lab/.virtualenvs/shoppingMall/lib/python3.6/site-packages/rest_framework/views.py", line 443, in handle_exception
    self.raise_uncaught_exception(exc)
  File "/home/changle-lab/.virtualenvs/shoppingMall/lib/python3.6/site-packages/rest_framework/views.py", line 480, in dispatch
    response = handler(request, *args, **kwargs)
  File "/home/changle-lab/Desktop/shopping_mall/shoppingMall/meiduo_mall/meiduo_mall/apps/oauth/views.py", line 74, in get
    return Response(self, {'login_url': login_url})
TypeError: __init__() takes 1 positional argument but 3 were given
ERROR 2019-09-12 19:21:30,187 basehttp 124 "GET /oauth/qq/authorization/?next=/ HTTP/1.1" 500 19032
INFO 2019-09-12 19:23:53,547 basehttp 124 "GET /oauth/qq/authorization/?next=/ HTTP/1.1" 200 195
INFO 2019-09-12 19:57:26,260 basehttp 124 "GET /oauth/qq/authorization/?next=/ HTTP/1.1" 200 175
WARNING 2019-09-12 19:57:43,432 base 152 Not Found: /oauth/qq/user/
WARNING 2019-09-12 19:57:43,434 basehttp 124 "GET /oauth/qq/user/?code=F0C08BEFFCC273AE277E1DE37B940879 HTTP/1.1" 404 3087
